INFO 2020-02-27 13:08:16,191 autoreload 578 Watching for file changes with StatReloader
INFO 2020-02-27 13:09:52,174 autoreload 578 Watching for file changes with StatReloader
INFO 2020-02-27 13:10:04,444 autoreload 203 /home/moluo/.virtualenvs/renran/lib/python3.6/site-packages/django/db/backends/mysql/operations.py changed, reloading.
INFO 2020-02-27 13:10:05,779 autoreload 578 Watching for file changes with StatReloader
INFO 2020-02-27 13:10:11,261 autoreload 578 Watching for file changes with StatReloader
INFO 2020-02-28 08:28:48,902 autoreload 578 Watching for file changes with StatReloader
INFO 2020-02-28 08:29:25,761 basehttp 154 "GET / HTTP/1.1" 200 16348
INFO 2020-02-28 08:29:25,814 basehttp 154 "GET /static/admin/css/fonts.css HTTP/1.1" 200 423
INFO 2020-02-28 08:29:26,036 basehttp 154 "GET /static/admin/fonts/Roboto-Light-webfont.woff HTTP/1.1" 200 85692
INFO 2020-02-28 08:29:26,038 basehttp 154 "GET /static/admin/fonts/Roboto-Bold-webfont.woff HTTP/1.1" 200 86184
INFO 2020-02-28 08:29:26,041 basehttp 154 "GET /static/admin/fonts/Roboto-Regular-webfont.woff HTTP/1.1" 200 85876
WARNING 2020-02-28 08:29:26,067 log 228 Not Found: /favicon.ico
WARNING 2020-02-28 08:29:26,067 basehttp 154 "GET /favicon.ico HTTP/1.1" 404 1979
INFO 2020-02-28 08:30:48,789 autoreload 578 Watching for file changes with StatReloader
ERROR 2020-02-28 08:30:52,996 exception 77 Invalid HTTP_HOST header: 'api.renran.cn:8000'. You may need to add 'api.renran.cn' to ALLOWED_HOSTS.
WARNING 2020-02-28 08:30:53,189 log 228 Bad Request: /
WARNING 2020-02-28 08:30:53,191 basehttp 154 "GET / HTTP/1.1" 400 66873
ERROR 2020-02-28 08:31:15,781 exception 77 Invalid HTTP_HOST header: 'api.renran.cn:8000'. You may need to add 'api.renran.cn' to ALLOWED_HOSTS.
INFO 2020-02-28 08:31:15,799 autoreload 203 /home/moluo/Desktop/renran/renranapi/renranapi/settings/dev.py changed, reloading.
INFO 2020-02-28 08:31:17,659 autoreload 578 Watching for file changes with StatReloader
INFO 2020-02-28 08:31:19,320 basehttp 154 "GET / HTTP/1.1" 200 16348
INFO 2020-02-28 08:31:54,423 autoreload 578 Watching for file changes with StatReloader
INFO 2020-02-28 08:31:59,338 basehttp 154 "GET / HTTP/1.1" 200 16348
INFO 2020-02-28 08:33:14,842 autoreload 203 /home/moluo/Desktop/renran/renranapi/renranapi/settings/dev.py changed, reloading.
INFO 2020-02-28 08:33:15,801 autoreload 578 Watching for file changes with StatReloader
INFO 2020-02-28 08:33:33,464 autoreload 203 /home/moluo/Desktop/renran/renranapi/renranapi/settings/dev.py changed, reloading.
INFO 2020-02-28 08:33:34,619 autoreload 578 Watching for file changes with StatReloader
INFO 2020-02-28 08:37:04,919 autoreload 203 /home/moluo/Desktop/renran/renranapi/renranapi/settings/dev.py changed, reloading.
INFO 2020-02-28 08:37:05,906 autoreload 578 Watching for file changes with StatReloader
INFO 2020-02-28 09:28:21,828 autoreload 203 /home/moluo/Desktop/renran/renranapi/renranapi/settings/dev.py changed, reloading.
INFO 2020-02-28 09:28:25,273 autoreload 578 Watching for file changes with StatReloader
INFO 2020-02-28 09:29:20,349 autoreload 203 /home/moluo/Desktop/renran/renranapi/renranapi/apps/users/models.py changed, reloading.
INFO 2020-02-28 09:29:22,326 autoreload 578 Watching for file changes with StatReloader
INFO 2020-02-28 09:30:17,987 autoreload 203 /home/moluo/Desktop/renran/renranapi/renranapi/apps/users/models.py changed, reloading.
INFO 2020-02-28 09:30:19,200 autoreload 578 Watching for file changes with StatReloader
INFO 2020-02-28 09:31:31,403 autoreload 203 /home/moluo/Desktop/renran/renranapi/renranapi/apps/users/models.py changed, reloading.
INFO 2020-02-28 09:31:32,954 autoreload 578 Watching for file changes with StatReloader
INFO 2020-02-28 09:32:41,247 autoreload 203 /home/moluo/Desktop/renran/renranapi/renranapi/apps/users/models.py changed, reloading.
INFO 2020-02-28 09:32:42,687 autoreload 578 Watching for file changes with StatReloader
INFO 2020-02-28 09:33:37,918 autoreload 203 /home/moluo/Desktop/renran/renranapi/renranapi/settings/dev.py changed, reloading.
INFO 2020-02-28 09:33:39,098 autoreload 578 Watching for file changes with StatReloader
INFO 2020-03-02 11:40:46,413 autoreload 203 /home/moluo/Desktop/renran/renranapi/renranapi/settings/dev.py changed, reloading.
INFO 2020-03-02 11:40:48,737 autoreload 578 Watching for file changes with StatReloader
INFO 2020-03-02 11:46:52,994 autoreload 203 /home/moluo/Desktop/renran/renranapi/renranapi/urls.py changed, reloading.
INFO 2020-03-02 11:46:54,066 autoreload 578 Watching for file changes with StatReloader
INFO 2020-03-02 11:49:22,583 autoreload 578 Watching for file changes with StatReloader
WARNING 2020-03-02 11:49:33,629 log 228 Not Found: /
WARNING 2020-03-02 11:49:33,632 basehttp 154 "GET / HTTP/1.1" 404 2034
WARNING 2020-03-02 11:49:43,553 log 228 Not Found: /favicon.ico
WARNING 2020-03-02 11:49:43,554 basehttp 154 "GET /favicon.ico HTTP/1.1" 404 2085
INFO 2020-03-02 12:12:30,748 basehttp 154 "GET /users/login HTTP/1.1" 301 0
ERROR 2020-03-02 12:12:31,016 log 228 Internal Server Error: /users/login/
Traceback (most recent call last):
  File "/home/moluo/.virtualenvs/renran/lib/python3.6/site-packages/django/core/handlers/exception.py", line 34, in inner
    response = get_response(request)
  File "/home/moluo/.virtualenvs/renran/lib/python3.6/site-packages/django/core/handlers/base.py", line 145, in _get_response
    response = self.process_exception_by_middleware(e, request)
  File "/home/moluo/.virtualenvs/renran/lib/python3.6/site-packages/django/core/handlers/base.py", line 143, in _get_response
    response = response.render()
  File "/home/moluo/.virtualenvs/renran/lib/python3.6/site-packages/django/template/response.py", line 106, in render
    self.content = self.rendered_content
  File "/home/moluo/.virtualenvs/renran/lib/python3.6/site-packages/rest_framework/response.py", line 70, in rendered_content
    ret = renderer.render(self.data, accepted_media_type, context)
  File "/home/moluo/.virtualenvs/renran/lib/python3.6/site-packages/rest_framework/renderers.py", line 723, in render
    template = loader.get_template(self.template)
  File "/home/moluo/.virtualenvs/renran/lib/python3.6/site-packages/django/template/loader.py", line 19, in get_template
    raise TemplateDoesNotExist(template_name, chain=chain)
django.template.exceptions.TemplateDoesNotExist: rest_framework/api.html
ERROR 2020-03-02 12:12:31,024 basehttp 154 "GET /users/login/ HTTP/1.1" 500 86489
WARNING 2020-03-02 12:12:42,087 log 228 Not Found: /users/
WARNING 2020-03-02 12:12:42,089 basehttp 154 "GET /users/ HTTP/1.1" 404 2284
ERROR 2020-03-02 12:12:52,015 log 228 Internal Server Error: /users/login/
Traceback (most recent call last):
  File "/home/moluo/.virtualenvs/renran/lib/python3.6/site-packages/django/core/handlers/exception.py", line 34, in inner
    response = get_response(request)
  File "/home/moluo/.virtualenvs/renran/lib/python3.6/site-packages/django/core/handlers/base.py", line 145, in _get_response
    response = self.process_exception_by_middleware(e, request)
  File "/home/moluo/.virtualenvs/renran/lib/python3.6/site-packages/django/core/handlers/base.py", line 143, in _get_response
    response = response.render()
  File "/home/moluo/.virtualenvs/renran/lib/python3.6/site-packages/django/template/response.py", line 106, in render
    self.content = self.rendered_content
  File "/home/moluo/.virtualenvs/renran/lib/python3.6/site-packages/rest_framework/response.py", line 70, in rendered_content
    ret = renderer.render(self.data, accepted_media_type, context)
  File "/home/moluo/.virtualenvs/renran/lib/python3.6/site-packages/rest_framework/renderers.py", line 723, in render
    template = loader.get_template(self.template)
  File "/home/moluo/.virtualenvs/renran/lib/python3.6/site-packages/django/template/loader.py", line 19, in get_template
    raise TemplateDoesNotExist(template_name, chain=chain)
django.template.exceptions.TemplateDoesNotExist: rest_framework/api.html
ERROR 2020-03-02 12:12:52,018 basehttp 154 "GET /users/login/ HTTP/1.1" 500 86489
ERROR 2020-03-02 12:12:55,828 log 228 Internal Server Error: /users/login/
Traceback (most recent call last):
  File "/home/moluo/.virtualenvs/renran/lib/python3.6/site-packages/django/core/handlers/exception.py", line 34, in inner
    response = get_response(request)
  File "/home/moluo/.virtualenvs/renran/lib/python3.6/site-packages/django/core/handlers/base.py", line 145, in _get_response
    response = self.process_exception_by_middleware(e, request)
  File "/home/moluo/.virtualenvs/renran/lib/python3.6/site-packages/django/core/handlers/base.py", line 143, in _get_response
    response = response.render()
  File "/home/moluo/.virtualenvs/renran/lib/python3.6/site-packages/django/template/response.py", line 106, in render
    self.content = self.rendered_content
  File "/home/moluo/.virtualenvs/renran/lib/python3.6/site-packages/rest_framework/response.py", line 70, in rendered_content
    ret = renderer.render(self.data, accepted_media_type, context)
  File "/home/moluo/.virtualenvs/renran/lib/python3.6/site-packages/rest_framework/renderers.py", line 723, in render
    template = loader.get_template(self.template)
  File "/home/moluo/.virtualenvs/renran/lib/python3.6/site-packages/django/template/loader.py", line 19, in get_template
    raise TemplateDoesNotExist(template_name, chain=chain)
django.template.exceptions.TemplateDoesNotExist: rest_framework/api.html
ERROR 2020-03-02 12:12:55,839 basehttp 154 "GET /users/login/ HTTP/1.1" 500 86489
WARNING 2020-03-02 12:14:55,510 log 228 Bad Request: /users/login/
WARNING 2020-03-02 12:14:55,513 basehttp 154 "POST /users/login/ HTTP/1.1" 400 79
WARNING 2020-03-02 12:15:37,313 log 228 Bad Request: /users/login/
WARNING 2020-03-02 12:15:37,315 basehttp 154 "POST /users/login/ HTTP/1.1" 400 108
INFO 2020-03-02 12:15:51,921 basehttp 154 "POST /users/login/ HTTP/1.1" 200 195
INFO 2020-03-02 12:16:24,647 basehttp 154 "POST /users/login/ HTTP/1.1" 200 195
INFO 2020-03-02 12:19:34,996 autoreload 203 /home/moluo/Desktop/renran/renranapi/renranapi/apps/users/models.py changed, reloading.
INFO 2020-03-02 12:19:37,187 autoreload 578 Watching for file changes with StatReloader
INFO 2020-03-02 12:20:31,720 autoreload 578 Watching for file changes with StatReloader
INFO 2020-03-02 12:20:36,031 basehttp 154 "POST /users/login/ HTTP/1.1" 200 195
INFO 2020-03-02 12:24:50,990 autoreload 203 /home/moluo/Desktop/renran/renranapi/renranapi/settings/dev.py changed, reloading.
INFO 2020-03-02 12:24:52,390 autoreload 578 Watching for file changes with StatReloader
INFO 2020-03-02 12:36:46,339 autoreload 203 /home/moluo/Desktop/renran/renranapi/renranapi/apps/users/utils.py changed, reloading.
INFO 2020-03-02 12:36:47,850 autoreload 578 Watching for file changes with StatReloader
INFO 2020-03-02 21:22:06,011 autoreload 578 Watching for file changes with StatReloader
INFO 2020-03-02 21:23:09,442 autoreload 578 Watching for file changes with StatReloader
INFO 2020-03-02 21:24:27,895 autoreload 578 Watching for file changes with StatReloader
INFO 2020-03-02 21:24:44,269 autoreload 578 Watching for file changes with StatReloader
INFO 2020-03-02 21:24:51,078 autoreload 578 Watching for file changes with StatReloader
INFO 2020-03-02 21:24:56,202 autoreload 578 Watching for file changes with StatReloader
INFO 2020-03-02 21:25:03,806 autoreload 578 Watching for file changes with StatReloader
INFO 2020-03-02 21:26:06,063 autoreload 578 Watching for file changes with StatReloader
INFO 2020-03-02 21:26:18,738 autoreload 578 Watching for file changes with StatReloader
INFO 2020-03-02 21:26:25,803 autoreload 578 Watching for file changes with StatReloader
INFO 2020-03-02 21:27:02,122 autoreload 578 Watching for file changes with StatReloader
INFO 2020-03-02 21:27:57,085 autoreload 578 Watching for file changes with StatReloader
INFO 2020-03-02 21:28:33,090 autoreload 578 Watching for file changes with StatReloader
INFO 2020-03-02 21:30:50,992 autoreload 578 Watching for file changes with StatReloader
INFO 2020-03-02 21:35:08,343 autoreload 578 Watching for file changes with StatReloader
INFO 2020-03-02 21:35:27,877 autoreload 578 Watching for file changes with StatReloader
WARNING 2020-03-02 21:35:41,183 log 228 Not Found: /
WARNING 2020-03-02 21:35:41,202 basehttp 154 "GET / HTTP/1.1" 404 2035
INFO 2020-03-02 21:35:55,930 basehttp 154 "GET /xadmin/ HTTP/1.1" 200 4151
INFO 2020-03-02 21:35:56,092 basehttp 154 "GET /static/xadmin/css/themes/bootstrap-xadmin.css HTTP/1.1" 200 1888
INFO 2020-03-02 21:35:56,096 basehttp 154 "GET /static/xadmin/vendor/bootstrap/css/bootstrap.css HTTP/1.1" 200 126432
INFO 2020-03-02 21:35:56,154 basehttp 154 "GET /static/xadmin/css/xadmin.plugins.css HTTP/1.1" 200 175
INFO 2020-03-02 21:35:56,175 basehttp 154 "GET /static/xadmin/vendor/font-awesome/css/font-awesome.css HTTP/1.1" 200 21658
INFO 2020-03-02 21:35:56,182 basehttp 154 "GET /static/xadmin/css/xadmin.main.css HTTP/1.1" 200 8376
INFO 2020-03-02 21:35:56,183 basehttp 154 "GET /static/xadmin/css/xadmin.responsive.css HTTP/1.1" 200 4361
INFO 2020-03-02 21:35:56,185 basehttp 154 "GET /static/xadmin/vendor/jquery/jquery.js HTTP/1.1" 200 240196
INFO 2020-03-02 21:35:56,187 basehttp 154 "GET /static/xadmin/vendor/jquery-ui/jquery.ui.core.js HTTP/1.1" 200 8195
INFO 2020-03-02 21:35:56,244 basehttp 154 "GET /static/xadmin/vendor/jquery-ui/jquery.ui.widget.js HTTP/1.1" 200 15069
INFO 2020-03-02 21:35:56,262 basehttp 154 "GET /xadmin/jsi18n/ HTTP/1.1" 200 4158
INFO 2020-03-02 21:35:56,267 basehttp 154 "GET /static/xadmin/vendor/jquery-ui/jquery.ui.mouse.js HTTP/1.1" 200 4561
INFO 2020-03-02 21:35:56,270 basehttp 154 "GET /static/xadmin/js/xadmin.main.js HTTP/1.1" 200 3401
INFO 2020-03-02 21:35:56,277 basehttp 154 "GET /static/xadmin/vendor/jquery-ui/jquery.ui.sortable.js HTTP/1.1" 200 42543
INFO 2020-03-02 21:35:56,277 basehttp 154 "GET /static/xadmin/vendor/bootstrap/js/bootstrap.js HTTP/1.1" 200 58327
INFO 2020-03-02 21:35:56,302 basehttp 154 "GET /static/xadmin/js/xadmin.responsive.js HTTP/1.1" 200 4165
INFO 2020-03-02 21:35:56,656 basehttp 154 "GET /static/xadmin/vendor/font-awesome/fonts/fontawesome-webfont.woff?v=4.0.3 HTTP/1.1" 200 44432
INFO 2020-03-02 21:36:03,219 basehttp 154 "POST /xadmin/ HTTP/1.1" 302 0
ERROR 2020-03-02 21:36:03,526 log 228 Internal Server Error: /xadmin/
Traceback (most recent call last):
  File "/home/moluo/.virtualenvs/renran/lib/python3.6/site-packages/django/db/backends/utils.py", line 84, in _execute
    return self.cursor.execute(sql, params)
  File "/home/moluo/.virtualenvs/renran/lib/python3.6/site-packages/django/db/backends/mysql/base.py", line 71, in execute
    return self.cursor.execute(query, args)
  File "/home/moluo/.virtualenvs/renran/lib/python3.6/site-packages/pymysql/cursors.py", line 170, in execute
    result = self._query(query)
  File "/home/moluo/.virtualenvs/renran/lib/python3.6/site-packages/pymysql/cursors.py", line 328, in _query
    conn.query(q)
  File "/home/moluo/.virtualenvs/renran/lib/python3.6/site-packages/pymysql/connections.py", line 517, in query
    self._affected_rows = self._read_query_result(unbuffered=unbuffered)
  File "/home/moluo/.virtualenvs/renran/lib/python3.6/site-packages/pymysql/connections.py", line 732, in _read_query_result
    result.read()
  File "/home/moluo/.virtualenvs/renran/lib/python3.6/site-packages/pymysql/connections.py", line 1075, in read
    first_packet = self.connection._read_packet()
  File "/home/moluo/.virtualenvs/renran/lib/python3.6/site-packages/pymysql/connections.py", line 684, in _read_packet
    packet.check_error()
  File "/home/moluo/.virtualenvs/renran/lib/python3.6/site-packages/pymysql/protocol.py", line 220, in check_error
    err.raise_mysql_exception(self._data)
  File "/home/moluo/.virtualenvs/renran/lib/python3.6/site-packages/pymysql/err.py", line 109, in raise_mysql_exception
    raise errorclass(errno, errval)
pymysql.err.ProgrammingError: (1146, "Table 'renran.xadmin_usersettings' doesn't exist")

The above exception was the direct cause of the following exception:

Traceback (most recent call last):
  File "/home/moluo/.virtualenvs/renran/lib/python3.6/site-packages/django/core/handlers/exception.py", line 34, in inner
    response = get_response(request)
  File "/home/moluo/.virtualenvs/renran/lib/python3.6/site-packages/django/core/handlers/base.py", line 115, in _get_response
    response = self.process_exception_by_middleware(e, request)
  File "/home/moluo/.virtualenvs/renran/lib/python3.6/site-packages/django/core/handlers/base.py", line 113, in _get_response
    response = wrapped_callback(request, *callback_args, **callback_kwargs)
  File "/home/moluo/.virtualenvs/renran/lib/python3.6/site-packages/xadmin/sites.py", line 300, in wrapper
    return self.admin_view(view, cacheable)(*args, **kwargs)
  File "/home/moluo/.virtualenvs/renran/lib/python3.6/site-packages/django/views/decorators/cache.py", line 44, in _wrapped_view_func
    response = view_func(request, *args, **kwargs)
  File "/home/moluo/.virtualenvs/renran/lib/python3.6/site-packages/xadmin/sites.py", line 208, in inner
    return view(request, *args, **kwargs)
  File "/home/moluo/.virtualenvs/renran/lib/python3.6/site-packages/xadmin/views/base.py", line 282, in view
    return handler(request, *args, **kwargs)
  File "/home/moluo/.virtualenvs/renran/lib/python3.6/site-packages/django/views/decorators/cache.py", line 44, in _wrapped_view_func
    response = view_func(request, *args, **kwargs)
  File "/home/moluo/.virtualenvs/renran/lib/python3.6/site-packages/xadmin/views/dashboard.py", line 592, in get
    self.widgets = self.get_widgets()
  File "/home/moluo/.virtualenvs/renran/lib/python3.6/site-packages/xadmin/views/base.py", line 80, in method
    return filter_chain(filters, len(filters) - 1, _inner_method, *args, **kwargs)
  File "/home/moluo/.virtualenvs/renran/lib/python3.6/site-packages/xadmin/views/base.py", line 49, in filter_chain
    return func()
  File "/home/moluo/.virtualenvs/renran/lib/python3.6/site-packages/xadmin/views/base.py", line 74, in _inner_method
    return func(self, *args, **kwargs)
  File "/home/moluo/.virtualenvs/renran/lib/python3.6/site-packages/xadmin/views/dashboard.py", line 549, in get_widgets
    if len(portal_pos):
  File "/home/moluo/.virtualenvs/renran/lib/python3.6/site-packages/django/db/models/query.py", line 256, in __len__
    self._fetch_all()
  File "/home/moluo/.virtualenvs/renran/lib/python3.6/site-packages/django/db/models/query.py", line 1242, in _fetch_all
    self._result_cache = list(self._iterable_class(self))
  File "/home/moluo/.virtualenvs/renran/lib/python3.6/site-packages/django/db/models/query.py", line 55, in __iter__
    results = compiler.execute_sql(chunked_fetch=self.chunked_fetch, chunk_size=self.chunk_size)
  File "/home/moluo/.virtualenvs/renran/lib/python3.6/site-packages/django/db/models/sql/compiler.py", line 1097, in execute_sql
    cursor.execute(sql, params)
  File "/home/moluo/.virtualenvs/renran/lib/python3.6/site-packages/django/db/backends/utils.py", line 99, in execute
    return super().execute(sql, params)
  File "/home/moluo/.virtualenvs/renran/lib/python3.6/site-packages/django/db/backends/utils.py", line 67, in execute
    return self._execute_with_wrappers(sql, params, many=False, executor=self._execute)
  File "/home/moluo/.virtualenvs/renran/lib/python3.6/site-packages/django/db/backends/utils.py", line 76, in _execute_with_wrappers
    return executor(sql, params, many, context)
  File "/home/moluo/.virtualenvs/renran/lib/python3.6/site-packages/django/db/backends/utils.py", line 84, in _execute
    return self.cursor.execute(sql, params)
  File "/home/moluo/.virtualenvs/renran/lib/python3.6/site-packages/django/db/utils.py", line 89, in __exit__
    raise dj_exc_value.with_traceback(traceback) from exc_value
  File "/home/moluo/.virtualenvs/renran/lib/python3.6/site-packages/django/db/backends/utils.py", line 84, in _execute
    return self.cursor.execute(sql, params)
  File "/home/moluo/.virtualenvs/renran/lib/python3.6/site-packages/django/db/backends/mysql/base.py", line 71, in execute
    return self.cursor.execute(query, args)
  File "/home/moluo/.virtualenvs/renran/lib/python3.6/site-packages/pymysql/cursors.py", line 170, in execute
    result = self._query(query)
  File "/home/moluo/.virtualenvs/renran/lib/python3.6/site-packages/pymysql/cursors.py", line 328, in _query
    conn.query(q)
  File "/home/moluo/.virtualenvs/renran/lib/python3.6/site-packages/pymysql/connections.py", line 517, in query
    self._affected_rows = self._read_query_result(unbuffered=unbuffered)
  File "/home/moluo/.virtualenvs/renran/lib/python3.6/site-packages/pymysql/connections.py", line 732, in _read_query_result
    result.read()
  File "/home/moluo/.virtualenvs/renran/lib/python3.6/site-packages/pymysql/connections.py", line 1075, in read
    first_packet = self.connection._read_packet()
  File "/home/moluo/.virtualenvs/renran/lib/python3.6/site-packages/pymysql/connections.py", line 684, in _read_packet
    packet.check_error()
  File "/home/moluo/.virtualenvs/renran/lib/python3.6/site-packages/pymysql/protocol.py", line 220, in check_error
    err.raise_mysql_exception(self._data)
  File "/home/moluo/.virtualenvs/renran/lib/python3.6/site-packages/pymysql/err.py", line 109, in raise_mysql_exception
    raise errorclass(errno, errval)
django.db.utils.ProgrammingError: (1146, "Table 'renran.xadmin_usersettings' doesn't exist")
ERROR 2020-03-02 21:36:03,538 basehttp 154 "GET /xadmin/ HTTP/1.1" 500 239761
INFO 2020-03-02 21:37:02,102 autoreload 578 Watching for file changes with StatReloader
INFO 2020-03-02 21:37:44,481 autoreload 578 Watching for file changes with StatReloader
INFO 2020-03-02 21:39:21,767 autoreload 578 Watching for file changes with StatReloader
INFO 2020-03-02 21:39:56,603 autoreload 578 Watching for file changes with StatReloader
WARNING 2020-03-02 21:40:11,749 log 228 Not Found: /
WARNING 2020-03-02 21:40:11,808 basehttp 154 "GET / HTTP/1.1" 404 2035
ERROR 2020-03-02 21:40:22,601 log 228 Internal Server Error: /xadmin/
Traceback (most recent call last):
  File "/home/moluo/.virtualenvs/renran/lib/python3.6/site-packages/django/db/backends/utils.py", line 84, in _execute
    return self.cursor.execute(sql, params)
  File "/home/moluo/.virtualenvs/renran/lib/python3.6/site-packages/django/db/backends/mysql/base.py", line 71, in execute
    return self.cursor.execute(query, args)
  File "/home/moluo/.virtualenvs/renran/lib/python3.6/site-packages/pymysql/cursors.py", line 170, in execute
    result = self._query(query)
  File "/home/moluo/.virtualenvs/renran/lib/python3.6/site-packages/pymysql/cursors.py", line 328, in _query
    conn.query(q)
  File "/home/moluo/.virtualenvs/renran/lib/python3.6/site-packages/pymysql/connections.py", line 517, in query
    self._affected_rows = self._read_query_result(unbuffered=unbuffered)
  File "/home/moluo/.virtualenvs/renran/lib/python3.6/site-packages/pymysql/connections.py", line 732, in _read_query_result
    result.read()
  File "/home/moluo/.virtualenvs/renran/lib/python3.6/site-packages/pymysql/connections.py", line 1075, in read
    first_packet = self.connection._read_packet()
  File "/home/moluo/.virtualenvs/renran/lib/python3.6/site-packages/pymysql/connections.py", line 684, in _read_packet
    packet.check_error()
  File "/home/moluo/.virtualenvs/renran/lib/python3.6/site-packages/pymysql/protocol.py", line 220, in check_error
    err.raise_mysql_exception(self._data)
  File "/home/moluo/.virtualenvs/renran/lib/python3.6/site-packages/pymysql/err.py", line 109, in raise_mysql_exception
    raise errorclass(errno, errval)
pymysql.err.ProgrammingError: (1146, "Table 'renran.xadmin_usersettings' doesn't exist")

The above exception was the direct cause of the following exception:

Traceback (most recent call last):
  File "/home/moluo/.virtualenvs/renran/lib/python3.6/site-packages/django/core/handlers/exception.py", line 34, in inner
    response = get_response(request)
  File "/home/moluo/.virtualenvs/renran/lib/python3.6/site-packages/django/core/handlers/base.py", line 115, in _get_response
    response = self.process_exception_by_middleware(e, request)
  File "/home/moluo/.virtualenvs/renran/lib/python3.6/site-packages/django/core/handlers/base.py", line 113, in _get_response
    response = wrapped_callback(request, *callback_args, **callback_kwargs)
  File "/home/moluo/.virtualenvs/renran/lib/python3.6/site-packages/xadmin/sites.py", line 300, in wrapper
    return self.admin_view(view, cacheable)(*args, **kwargs)
  File "/home/moluo/.virtualenvs/renran/lib/python3.6/site-packages/django/views/decorators/cache.py", line 44, in _wrapped_view_func
    response = view_func(request, *args, **kwargs)
  File "/home/moluo/.virtualenvs/renran/lib/python3.6/site-packages/xadmin/sites.py", line 208, in inner
    return view(request, *args, **kwargs)
  File "/home/moluo/.virtualenvs/renran/lib/python3.6/site-packages/xadmin/views/base.py", line 282, in view
    return handler(request, *args, **kwargs)
  File "/home/moluo/.virtualenvs/renran/lib/python3.6/site-packages/django/views/decorators/cache.py", line 44, in _wrapped_view_func
    response = view_func(request, *args, **kwargs)
  File "/home/moluo/.virtualenvs/renran/lib/python3.6/site-packages/xadmin/views/dashboard.py", line 592, in get
    self.widgets = self.get_widgets()
  File "/home/moluo/.virtualenvs/renran/lib/python3.6/site-packages/xadmin/views/base.py", line 80, in method
    return filter_chain(filters, len(filters) - 1, _inner_method, *args, **kwargs)
  File "/home/moluo/.virtualenvs/renran/lib/python3.6/site-packages/xadmin/views/base.py", line 49, in filter_chain
    return func()
  File "/home/moluo/.virtualenvs/renran/lib/python3.6/site-packages/xadmin/views/base.py", line 74, in _inner_method
    return func(self, *args, **kwargs)
  File "/home/moluo/.virtualenvs/renran/lib/python3.6/site-packages/xadmin/views/dashboard.py", line 549, in get_widgets
    if len(portal_pos):
  File "/home/moluo/.virtualenvs/renran/lib/python3.6/site-packages/django/db/models/query.py", line 256, in __len__
    self._fetch_all()
  File "/home/moluo/.virtualenvs/renran/lib/python3.6/site-packages/django/db/models/query.py", line 1242, in _fetch_all
    self._result_cache = list(self._iterable_class(self))
  File "/home/moluo/.virtualenvs/renran/lib/python3.6/site-packages/django/db/models/query.py", line 55, in __iter__
    results = compiler.execute_sql(chunked_fetch=self.chunked_fetch, chunk_size=self.chunk_size)
  File "/home/moluo/.virtualenvs/renran/lib/python3.6/site-packages/django/db/models/sql/compiler.py", line 1097, in execute_sql
    cursor.execute(sql, params)
  File "/home/moluo/.virtualenvs/renran/lib/python3.6/site-packages/django/db/backends/utils.py", line 99, in execute
    return super().execute(sql, params)
  File "/home/moluo/.virtualenvs/renran/lib/python3.6/site-packages/django/db/backends/utils.py", line 67, in execute
    return self._execute_with_wrappers(sql, params, many=False, executor=self._execute)
  File "/home/moluo/.virtualenvs/renran/lib/python3.6/site-packages/django/db/backends/utils.py", line 76, in _execute_with_wrappers
    return executor(sql, params, many, context)
  File "/home/moluo/.virtualenvs/renran/lib/python3.6/site-packages/django/db/backends/utils.py", line 84, in _execute
    return self.cursor.execute(sql, params)
  File "/home/moluo/.virtualenvs/renran/lib/python3.6/site-packages/django/db/utils.py", line 89, in __exit__
    raise dj_exc_value.with_traceback(traceback) from exc_value
  File "/home/moluo/.virtualenvs/renran/lib/python3.6/site-packages/django/db/backends/utils.py", line 84, in _execute
    return self.cursor.execute(sql, params)
  File "/home/moluo/.virtualenvs/renran/lib/python3.6/site-packages/django/db/backends/mysql/base.py", line 71, in execute
    return self.cursor.execute(query, args)
  File "/home/moluo/.virtualenvs/renran/lib/python3.6/site-packages/pymysql/cursors.py", line 170, in execute
    result = self._query(query)
  File "/home/moluo/.virtualenvs/renran/lib/python3.6/site-packages/pymysql/cursors.py", line 328, in _query
    conn.query(q)
  File "/home/moluo/.virtualenvs/renran/lib/python3.6/site-packages/pymysql/connections.py", line 517, in query
    self._affected_rows = self._read_query_result(unbuffered=unbuffered)
  File "/home/moluo/.virtualenvs/renran/lib/python3.6/site-packages/pymysql/connections.py", line 732, in _read_query_result
    result.read()
  File "/home/moluo/.virtualenvs/renran/lib/python3.6/site-packages/pymysql/connections.py", line 1075, in read
    first_packet = self.connection._read_packet()
  File "/home/moluo/.virtualenvs/renran/lib/python3.6/site-packages/pymysql/connections.py", line 684, in _read_packet
    packet.check_error()
  File "/home/moluo/.virtualenvs/renran/lib/python3.6/site-packages/pymysql/protocol.py", line 220, in check_error
    err.raise_mysql_exception(self._data)
  File "/home/moluo/.virtualenvs/renran/lib/python3.6/site-packages/pymysql/err.py", line 109, in raise_mysql_exception
    raise errorclass(errno, errval)
django.db.utils.ProgrammingError: (1146, "Table 'renran.xadmin_usersettings' doesn't exist")
ERROR 2020-03-02 21:40:22,614 basehttp 154 "GET /xadmin/ HTTP/1.1" 500 239651
INFO 2020-03-02 21:42:08,822 autoreload 578 Watching for file changes with StatReloader
ERROR 2020-03-02 21:42:17,604 log 228 Internal Server Error: /xadmin/
Traceback (most recent call last):
  File "/home/moluo/.virtualenvs/renran/lib/python3.6/site-packages/django/db/backends/utils.py", line 84, in _execute
    return self.cursor.execute(sql, params)
  File "/home/moluo/.virtualenvs/renran/lib/python3.6/site-packages/django/db/backends/mysql/base.py", line 71, in execute
    return self.cursor.execute(query, args)
  File "/home/moluo/.virtualenvs/renran/lib/python3.6/site-packages/pymysql/cursors.py", line 170, in execute
    result = self._query(query)
  File "/home/moluo/.virtualenvs/renran/lib/python3.6/site-packages/pymysql/cursors.py", line 328, in _query
    conn.query(q)
  File "/home/moluo/.virtualenvs/renran/lib/python3.6/site-packages/pymysql/connections.py", line 517, in query
    self._affected_rows = self._read_query_result(unbuffered=unbuffered)
  File "/home/moluo/.virtualenvs/renran/lib/python3.6/site-packages/pymysql/connections.py", line 732, in _read_query_result
    result.read()
  File "/home/moluo/.virtualenvs/renran/lib/python3.6/site-packages/pymysql/connections.py", line 1075, in read
    first_packet = self.connection._read_packet()
  File "/home/moluo/.virtualenvs/renran/lib/python3.6/site-packages/pymysql/connections.py", line 684, in _read_packet
    packet.check_error()
  File "/home/moluo/.virtualenvs/renran/lib/python3.6/site-packages/pymysql/protocol.py", line 220, in check_error
    err.raise_mysql_exception(self._data)
  File "/home/moluo/.virtualenvs/renran/lib/python3.6/site-packages/pymysql/err.py", line 109, in raise_mysql_exception
    raise errorclass(errno, errval)
pymysql.err.ProgrammingError: (1146, "Table 'renran.xadmin_usersettings' doesn't exist")

The above exception was the direct cause of the following exception:

Traceback (most recent call last):
  File "/home/moluo/.virtualenvs/renran/lib/python3.6/site-packages/django/core/handlers/exception.py", line 34, in inner
    response = get_response(request)
  File "/home/moluo/.virtualenvs/renran/lib/python3.6/site-packages/django/core/handlers/base.py", line 115, in _get_response
    response = self.process_exception_by_middleware(e, request)
  File "/home/moluo/.virtualenvs/renran/lib/python3.6/site-packages/django/core/handlers/base.py", line 113, in _get_response
    response = wrapped_callback(request, *callback_args, **callback_kwargs)
  File "/home/moluo/.virtualenvs/renran/lib/python3.6/site-packages/xadmin/sites.py", line 300, in wrapper
    return self.admin_view(view, cacheable)(*args, **kwargs)
  File "/home/moluo/.virtualenvs/renran/lib/python3.6/site-packages/django/views/decorators/cache.py", line 44, in _wrapped_view_func
    response = view_func(request, *args, **kwargs)
  File "/home/moluo/.virtualenvs/renran/lib/python3.6/site-packages/xadmin/sites.py", line 208, in inner
    return view(request, *args, **kwargs)
  File "/home/moluo/.virtualenvs/renran/lib/python3.6/site-packages/xadmin/views/base.py", line 282, in view
    return handler(request, *args, **kwargs)
  File "/home/moluo/.virtualenvs/renran/lib/python3.6/site-packages/django/views/decorators/cache.py", line 44, in _wrapped_view_func
    response = view_func(request, *args, **kwargs)
  File "/home/moluo/.virtualenvs/renran/lib/python3.6/site-packages/xadmin/views/dashboard.py", line 592, in get
    self.widgets = self.get_widgets()
  File "/home/moluo/.virtualenvs/renran/lib/python3.6/site-packages/xadmin/views/base.py", line 80, in method
    return filter_chain(filters, len(filters) - 1, _inner_method, *args, **kwargs)
  File "/home/moluo/.virtualenvs/renran/lib/python3.6/site-packages/xadmin/views/base.py", line 49, in filter_chain
    return func()
  File "/home/moluo/.virtualenvs/renran/lib/python3.6/site-packages/xadmin/views/base.py", line 74, in _inner_method
    return func(self, *args, **kwargs)
  File "/home/moluo/.virtualenvs/renran/lib/python3.6/site-packages/xadmin/views/dashboard.py", line 549, in get_widgets
    if len(portal_pos):
  File "/home/moluo/.virtualenvs/renran/lib/python3.6/site-packages/django/db/models/query.py", line 256, in __len__
    self._fetch_all()
  File "/home/moluo/.virtualenvs/renran/lib/python3.6/site-packages/django/db/models/query.py", line 1242, in _fetch_all
    self._result_cache = list(self._iterable_class(self))
  File "/home/moluo/.virtualenvs/renran/lib/python3.6/site-packages/django/db/models/query.py", line 55, in __iter__
    results = compiler.execute_sql(chunked_fetch=self.chunked_fetch, chunk_size=self.chunk_size)
  File "/home/moluo/.virtualenvs/renran/lib/python3.6/site-packages/django/db/models/sql/compiler.py", line 1097, in execute_sql
    cursor.execute(sql, params)
  File "/home/moluo/.virtualenvs/renran/lib/python3.6/site-packages/django/db/backends/utils.py", line 99, in execute
    return super().execute(sql, params)
  File "/home/moluo/.virtualenvs/renran/lib/python3.6/site-packages/django/db/backends/utils.py", line 67, in execute
    return self._execute_with_wrappers(sql, params, many=False, executor=self._execute)
  File "/home/moluo/.virtualenvs/renran/lib/python3.6/site-packages/django/db/backends/utils.py", line 76, in _execute_with_wrappers
    return executor(sql, params, many, context)
  File "/home/moluo/.virtualenvs/renran/lib/python3.6/site-packages/django/db/backends/utils.py", line 84, in _execute
    return self.cursor.execute(sql, params)
  File "/home/moluo/.virtualenvs/renran/lib/python3.6/site-packages/django/db/utils.py", line 89, in __exit__
    raise dj_exc_value.with_traceback(traceback) from exc_value
  File "/home/moluo/.virtualenvs/renran/lib/python3.6/site-packages/django/db/backends/utils.py", line 84, in _execute
    return self.cursor.execute(sql, params)
  File "/home/moluo/.virtualenvs/renran/lib/python3.6/site-packages/django/db/backends/mysql/base.py", line 71, in execute
    return self.cursor.execute(query, args)
  File "/home/moluo/.virtualenvs/renran/lib/python3.6/site-packages/pymysql/cursors.py", line 170, in execute
    result = self._query(query)
  File "/home/moluo/.virtualenvs/renran/lib/python3.6/site-packages/pymysql/cursors.py", line 328, in _query
    conn.query(q)
  File "/home/moluo/.virtualenvs/renran/lib/python3.6/site-packages/pymysql/connections.py", line 517, in query
    self._affected_rows = self._read_query_result(unbuffered=unbuffered)
  File "/home/moluo/.virtualenvs/renran/lib/python3.6/site-packages/pymysql/connections.py", line 732, in _read_query_result
    result.read()
  File "/home/moluo/.virtualenvs/renran/lib/python3.6/site-packages/pymysql/connections.py", line 1075, in read
    first_packet = self.connection._read_packet()
  File "/home/moluo/.virtualenvs/renran/lib/python3.6/site-packages/pymysql/connections.py", line 684, in _read_packet
    packet.check_error()
  File "/home/moluo/.virtualenvs/renran/lib/python3.6/site-packages/pymysql/protocol.py", line 220, in check_error
    err.raise_mysql_exception(self._data)
  File "/home/moluo/.virtualenvs/renran/lib/python3.6/site-packages/pymysql/err.py", line 109, in raise_mysql_exception
    raise errorclass(errno, errval)
django.db.utils.ProgrammingError: (1146, "Table 'renran.xadmin_usersettings' doesn't exist")
ERROR 2020-03-02 21:42:17,630 basehttp 154 "GET /xadmin/ HTTP/1.1" 500 239609
ERROR 2020-03-02 21:42:20,657 log 228 Internal Server Error: /xadmin/
Traceback (most recent call last):
  File "/home/moluo/.virtualenvs/renran/lib/python3.6/site-packages/django/db/backends/utils.py", line 84, in _execute
    return self.cursor.execute(sql, params)
  File "/home/moluo/.virtualenvs/renran/lib/python3.6/site-packages/django/db/backends/mysql/base.py", line 71, in execute
    return self.cursor.execute(query, args)
  File "/home/moluo/.virtualenvs/renran/lib/python3.6/site-packages/pymysql/cursors.py", line 170, in execute
    result = self._query(query)
  File "/home/moluo/.virtualenvs/renran/lib/python3.6/site-packages/pymysql/cursors.py", line 328, in _query
    conn.query(q)
  File "/home/moluo/.virtualenvs/renran/lib/python3.6/site-packages/pymysql/connections.py", line 517, in query
    self._affected_rows = self._read_query_result(unbuffered=unbuffered)
  File "/home/moluo/.virtualenvs/renran/lib/python3.6/site-packages/pymysql/connections.py", line 732, in _read_query_result
    result.read()
  File "/home/moluo/.virtualenvs/renran/lib/python3.6/site-packages/pymysql/connections.py", line 1075, in read
    first_packet = self.connection._read_packet()
  File "/home/moluo/.virtualenvs/renran/lib/python3.6/site-packages/pymysql/connections.py", line 684, in _read_packet
    packet.check_error()
  File "/home/moluo/.virtualenvs/renran/lib/python3.6/site-packages/pymysql/protocol.py", line 220, in check_error
    err.raise_mysql_exception(self._data)
  File "/home/moluo/.virtualenvs/renran/lib/python3.6/site-packages/pymysql/err.py", line 109, in raise_mysql_exception
    raise errorclass(errno, errval)
pymysql.err.ProgrammingError: (1146, "Table 'renran.xadmin_usersettings' doesn't exist")

The above exception was the direct cause of the following exception:

Traceback (most recent call last):
  File "/home/moluo/.virtualenvs/renran/lib/python3.6/site-packages/django/core/handlers/exception.py", line 34, in inner
    response = get_response(request)
  File "/home/moluo/.virtualenvs/renran/lib/python3.6/site-packages/django/core/handlers/base.py", line 115, in _get_response
    response = self.process_exception_by_middleware(e, request)
  File "/home/moluo/.virtualenvs/renran/lib/python3.6/site-packages/django/core/handlers/base.py", line 113, in _get_response
    response = wrapped_callback(request, *callback_args, **callback_kwargs)
  File "/home/moluo/.virtualenvs/renran/lib/python3.6/site-packages/xadmin/sites.py", line 300, in wrapper
    return self.admin_view(view, cacheable)(*args, **kwargs)
  File "/home/moluo/.virtualenvs/renran/lib/python3.6/site-packages/django/views/decorators/cache.py", line 44, in _wrapped_view_func
    response = view_func(request, *args, **kwargs)
  File "/home/moluo/.virtualenvs/renran/lib/python3.6/site-packages/xadmin/sites.py", line 208, in inner
    return view(request, *args, **kwargs)
  File "/home/moluo/.virtualenvs/renran/lib/python3.6/site-packages/xadmin/views/base.py", line 282, in view
    return handler(request, *args, **kwargs)
  File "/home/moluo/.virtualenvs/renran/lib/python3.6/site-packages/django/views/decorators/cache.py", line 44, in _wrapped_view_func
    response = view_func(request, *args, **kwargs)
  File "/home/moluo/.virtualenvs/renran/lib/python3.6/site-packages/xadmin/views/dashboard.py", line 592, in get
    self.widgets = self.get_widgets()
  File "/home/moluo/.virtualenvs/renran/lib/python3.6/site-packages/xadmin/views/base.py", line 80, in method
    return filter_chain(filters, len(filters) - 1, _inner_method, *args, **kwargs)
  File "/home/moluo/.virtualenvs/renran/lib/python3.6/site-packages/xadmin/views/base.py", line 49, in filter_chain
    return func()
  File "/home/moluo/.virtualenvs/renran/lib/python3.6/site-packages/xadmin/views/base.py", line 74, in _inner_method
    return func(self, *args, **kwargs)
  File "/home/moluo/.virtualenvs/renran/lib/python3.6/site-packages/xadmin/views/dashboard.py", line 549, in get_widgets
    if len(portal_pos):
  File "/home/moluo/.virtualenvs/renran/lib/python3.6/site-packages/django/db/models/query.py", line 256, in __len__
    self._fetch_all()
  File "/home/moluo/.virtualenvs/renran/lib/python3.6/site-packages/django/db/models/query.py", line 1242, in _fetch_all
    self._result_cache = list(self._iterable_class(self))
  File "/home/moluo/.virtualenvs/renran/lib/python3.6/site-packages/django/db/models/query.py", line 55, in __iter__
    results = compiler.execute_sql(chunked_fetch=self.chunked_fetch, chunk_size=self.chunk_size)
  File "/home/moluo/.virtualenvs/renran/lib/python3.6/site-packages/django/db/models/sql/compiler.py", line 1097, in execute_sql
    cursor.execute(sql, params)
  File "/home/moluo/.virtualenvs/renran/lib/python3.6/site-packages/django/db/backends/utils.py", line 99, in execute
    return super().execute(sql, params)
  File "/home/moluo/.virtualenvs/renran/lib/python3.6/site-packages/django/db/backends/utils.py", line 67, in execute
    return self._execute_with_wrappers(sql, params, many=False, executor=self._execute)
  File "/home/moluo/.virtualenvs/renran/lib/python3.6/site-packages/django/db/backends/utils.py", line 76, in _execute_with_wrappers
    return executor(sql, params, many, context)
  File "/home/moluo/.virtualenvs/renran/lib/python3.6/site-packages/django/db/backends/utils.py", line 84, in _execute
    return self.cursor.execute(sql, params)
  File "/home/moluo/.virtualenvs/renran/lib/python3.6/site-packages/django/db/utils.py", line 89, in __exit__
    raise dj_exc_value.with_traceback(traceback) from exc_value
  File "/home/moluo/.virtualenvs/renran/lib/python3.6/site-packages/django/db/backends/utils.py", line 84, in _execute
    return self.cursor.execute(sql, params)
  File "/home/moluo/.virtualenvs/renran/lib/python3.6/site-packages/django/db/backends/mysql/base.py", line 71, in execute
    return self.cursor.execute(query, args)
  File "/home/moluo/.virtualenvs/renran/lib/python3.6/site-packages/pymysql/cursors.py", line 170, in execute
    result = self._query(query)
  File "/home/moluo/.virtualenvs/renran/lib/python3.6/site-packages/pymysql/cursors.py", line 328, in _query
    conn.query(q)
  File "/home/moluo/.virtualenvs/renran/lib/python3.6/site-packages/pymysql/connections.py", line 517, in query
    self._affected_rows = self._read_query_result(unbuffered=unbuffered)
  File "/home/moluo/.virtualenvs/renran/lib/python3.6/site-packages/pymysql/connections.py", line 732, in _read_query_result
    result.read()
  File "/home/moluo/.virtualenvs/renran/lib/python3.6/site-packages/pymysql/connections.py", line 1075, in read
    first_packet = self.connection._read_packet()
  File "/home/moluo/.virtualenvs/renran/lib/python3.6/site-packages/pymysql/connections.py", line 684, in _read_packet
    packet.check_error()
  File "/home/moluo/.virtualenvs/renran/lib/python3.6/site-packages/pymysql/protocol.py", line 220, in check_error
    err.raise_mysql_exception(self._data)
  File "/home/moluo/.virtualenvs/renran/lib/python3.6/site-packages/pymysql/err.py", line 109, in raise_mysql_exception
    raise errorclass(errno, errval)
django.db.utils.ProgrammingError: (1146, "Table 'renran.xadmin_usersettings' doesn't exist")
ERROR 2020-03-02 21:42:20,660 basehttp 154 "GET /xadmin/ HTTP/1.1" 500 239609
ERROR 2020-03-02 21:42:44,098 log 228 Internal Server Error: /users/login/
Traceback (most recent call last):
  File "/home/moluo/.virtualenvs/renran/lib/python3.6/site-packages/django/core/handlers/exception.py", line 34, in inner
    response = get_response(request)
  File "/home/moluo/.virtualenvs/renran/lib/python3.6/site-packages/django/core/handlers/base.py", line 145, in _get_response
    response = self.process_exception_by_middleware(e, request)
  File "/home/moluo/.virtualenvs/renran/lib/python3.6/site-packages/django/core/handlers/base.py", line 143, in _get_response
    response = response.render()
  File "/home/moluo/.virtualenvs/renran/lib/python3.6/site-packages/django/template/response.py", line 106, in render
    self.content = self.rendered_content
  File "/home/moluo/.virtualenvs/renran/lib/python3.6/site-packages/rest_framework/response.py", line 70, in rendered_content
    ret = renderer.render(self.data, accepted_media_type, context)
  File "/home/moluo/.virtualenvs/renran/lib/python3.6/site-packages/rest_framework/renderers.py", line 723, in render
    template = loader.get_template(self.template)
  File "/home/moluo/.virtualenvs/renran/lib/python3.6/site-packages/django/template/loader.py", line 19, in get_template
    raise TemplateDoesNotExist(template_name, chain=chain)
django.template.exceptions.TemplateDoesNotExist: rest_framework/api.html
ERROR 2020-03-02 21:42:44,106 basehttp 154 "GET /users/login/ HTTP/1.1" 500 89343
INFO 2020-03-02 21:42:58,327 basehttp 154 "POST /users/login/ HTTP/1.1" 200 248
INFO 2020-03-02 21:43:30,173 autoreload 203 /home/moluo/Desktop/renran/renranapi/renranapi/apps/users/adminx.py changed, reloading.
INFO 2020-03-02 21:43:33,214 autoreload 578 Watching for file changes with StatReloader
ERROR 2020-03-02 21:43:38,315 log 228 Internal Server Error: /xadmin/
Traceback (most recent call last):
  File "/home/moluo/.virtualenvs/renran/lib/python3.6/site-packages/django/db/backends/utils.py", line 84, in _execute
    return self.cursor.execute(sql, params)
  File "/home/moluo/.virtualenvs/renran/lib/python3.6/site-packages/django/db/backends/mysql/base.py", line 71, in execute
    return self.cursor.execute(query, args)
  File "/home/moluo/.virtualenvs/renran/lib/python3.6/site-packages/pymysql/cursors.py", line 170, in execute
    result = self._query(query)
  File "/home/moluo/.virtualenvs/renran/lib/python3.6/site-packages/pymysql/cursors.py", line 328, in _query
    conn.query(q)
  File "/home/moluo/.virtualenvs/renran/lib/python3.6/site-packages/pymysql/connections.py", line 517, in query
    self._affected_rows = self._read_query_result(unbuffered=unbuffered)
  File "/home/moluo/.virtualenvs/renran/lib/python3.6/site-packages/pymysql/connections.py", line 732, in _read_query_result
    result.read()
  File "/home/moluo/.virtualenvs/renran/lib/python3.6/site-packages/pymysql/connections.py", line 1075, in read
    first_packet = self.connection._read_packet()
  File "/home/moluo/.virtualenvs/renran/lib/python3.6/site-packages/pymysql/connections.py", line 684, in _read_packet
    packet.check_error()
  File "/home/moluo/.virtualenvs/renran/lib/python3.6/site-packages/pymysql/protocol.py", line 220, in check_error
    err.raise_mysql_exception(self._data)
  File "/home/moluo/.virtualenvs/renran/lib/python3.6/site-packages/pymysql/err.py", line 109, in raise_mysql_exception
    raise errorclass(errno, errval)
pymysql.err.ProgrammingError: (1146, "Table 'renran.xadmin_usersettings' doesn't exist")

The above exception was the direct cause of the following exception:

Traceback (most recent call last):
  File "/home/moluo/.virtualenvs/renran/lib/python3.6/site-packages/django/core/handlers/exception.py", line 34, in inner
    response = get_response(request)
  File "/home/moluo/.virtualenvs/renran/lib/python3.6/site-packages/django/core/handlers/base.py", line 115, in _get_response
    response = self.process_exception_by_middleware(e, request)
  File "/home/moluo/.virtualenvs/renran/lib/python3.6/site-packages/django/core/handlers/base.py", line 113, in _get_response
    response = wrapped_callback(request, *callback_args, **callback_kwargs)
  File "/home/moluo/.virtualenvs/renran/lib/python3.6/site-packages/xadmin/sites.py", line 300, in wrapper
    return self.admin_view(view, cacheable)(*args, **kwargs)
  File "/home/moluo/.virtualenvs/renran/lib/python3.6/site-packages/django/views/decorators/cache.py", line 44, in _wrapped_view_func
    response = view_func(request, *args, **kwargs)
  File "/home/moluo/.virtualenvs/renran/lib/python3.6/site-packages/xadmin/sites.py", line 208, in inner
    return view(request, *args, **kwargs)
  File "/home/moluo/.virtualenvs/renran/lib/python3.6/site-packages/xadmin/views/base.py", line 282, in view
    return handler(request, *args, **kwargs)
  File "/home/moluo/.virtualenvs/renran/lib/python3.6/site-packages/django/views/decorators/cache.py", line 44, in _wrapped_view_func
    response = view_func(request, *args, **kwargs)
  File "/home/moluo/.virtualenvs/renran/lib/python3.6/site-packages/xadmin/views/dashboard.py", line 592, in get
    self.widgets = self.get_widgets()
  File "/home/moluo/.virtualenvs/renran/lib/python3.6/site-packages/xadmin/views/base.py", line 80, in method
    return filter_chain(filters, len(filters) - 1, _inner_method, *args, **kwargs)
  File "/home/moluo/.virtualenvs/renran/lib/python3.6/site-packages/xadmin/views/base.py", line 49, in filter_chain
    return func()
  File "/home/moluo/.virtualenvs/renran/lib/python3.6/site-packages/xadmin/views/base.py", line 74, in _inner_method
    return func(self, *args, **kwargs)
  File "/home/moluo/.virtualenvs/renran/lib/python3.6/site-packages/xadmin/views/dashboard.py", line 549, in get_widgets
    if len(portal_pos):
  File "/home/moluo/.virtualenvs/renran/lib/python3.6/site-packages/django/db/models/query.py", line 256, in __len__
    self._fetch_all()
  File "/home/moluo/.virtualenvs/renran/lib/python3.6/site-packages/django/db/models/query.py", line 1242, in _fetch_all
    self._result_cache = list(self._iterable_class(self))
  File "/home/moluo/.virtualenvs/renran/lib/python3.6/site-packages/django/db/models/query.py", line 55, in __iter__
    results = compiler.execute_sql(chunked_fetch=self.chunked_fetch, chunk_size=self.chunk_size)
  File "/home/moluo/.virtualenvs/renran/lib/python3.6/site-packages/django/db/models/sql/compiler.py", line 1097, in execute_sql
    cursor.execute(sql, params)
  File "/home/moluo/.virtualenvs/renran/lib/python3.6/site-packages/django/db/backends/utils.py", line 99, in execute
    return super().execute(sql, params)
  File "/home/moluo/.virtualenvs/renran/lib/python3.6/site-packages/django/db/backends/utils.py", line 67, in execute
    return self._execute_with_wrappers(sql, params, many=False, executor=self._execute)
  File "/home/moluo/.virtualenvs/renran/lib/python3.6/site-packages/django/db/backends/utils.py", line 76, in _execute_with_wrappers
    return executor(sql, params, many, context)
  File "/home/moluo/.virtualenvs/renran/lib/python3.6/site-packages/django/db/backends/utils.py", line 84, in _execute
    return self.cursor.execute(sql, params)
  File "/home/moluo/.virtualenvs/renran/lib/python3.6/site-packages/django/db/utils.py", line 89, in __exit__
    raise dj_exc_value.with_traceback(traceback) from exc_value
  File "/home/moluo/.virtualenvs/renran/lib/python3.6/site-packages/django/db/backends/utils.py", line 84, in _execute
    return self.cursor.execute(sql, params)
  File "/home/moluo/.virtualenvs/renran/lib/python3.6/site-packages/django/db/backends/mysql/base.py", line 71, in execute
    return self.cursor.execute(query, args)
  File "/home/moluo/.virtualenvs/renran/lib/python3.6/site-packages/pymysql/cursors.py", line 170, in execute
    result = self._query(query)
  File "/home/moluo/.virtualenvs/renran/lib/python3.6/site-packages/pymysql/cursors.py", line 328, in _query
    conn.query(q)
  File "/home/moluo/.virtualenvs/renran/lib/python3.6/site-packages/pymysql/connections.py", line 517, in query
    self._affected_rows = self._read_query_result(unbuffered=unbuffered)
  File "/home/moluo/.virtualenvs/renran/lib/python3.6/site-packages/pymysql/connections.py", line 732, in _read_query_result
    result.read()
  File "/home/moluo/.virtualenvs/renran/lib/python3.6/site-packages/pymysql/connections.py", line 1075, in read
    first_packet = self.connection._read_packet()
  File "/home/moluo/.virtualenvs/renran/lib/python3.6/site-packages/pymysql/connections.py", line 684, in _read_packet
    packet.check_error()
  File "/home/moluo/.virtualenvs/renran/lib/python3.6/site-packages/pymysql/protocol.py", line 220, in check_error
    err.raise_mysql_exception(self._data)
  File "/home/moluo/.virtualenvs/renran/lib/python3.6/site-packages/pymysql/err.py", line 109, in raise_mysql_exception
    raise errorclass(errno, errval)
django.db.utils.ProgrammingError: (1146, "Table 'renran.xadmin_usersettings' doesn't exist")
ERROR 2020-03-02 21:43:38,339 basehttp 154 "GET /xadmin/ HTTP/1.1" 500 239384
ERROR 2020-03-02 21:43:40,664 log 228 Internal Server Error: /xadmin/
Traceback (most recent call last):
  File "/home/moluo/.virtualenvs/renran/lib/python3.6/site-packages/django/db/backends/utils.py", line 84, in _execute
    return self.cursor.execute(sql, params)
  File "/home/moluo/.virtualenvs/renran/lib/python3.6/site-packages/django/db/backends/mysql/base.py", line 71, in execute
    return self.cursor.execute(query, args)
  File "/home/moluo/.virtualenvs/renran/lib/python3.6/site-packages/pymysql/cursors.py", line 170, in execute
    result = self._query(query)
  File "/home/moluo/.virtualenvs/renran/lib/python3.6/site-packages/pymysql/cursors.py", line 328, in _query
    conn.query(q)
  File "/home/moluo/.virtualenvs/renran/lib/python3.6/site-packages/pymysql/connections.py", line 517, in query
    self._affected_rows = self._read_query_result(unbuffered=unbuffered)
  File "/home/moluo/.virtualenvs/renran/lib/python3.6/site-packages/pymysql/connections.py", line 732, in _read_query_result
    result.read()
  File "/home/moluo/.virtualenvs/renran/lib/python3.6/site-packages/pymysql/connections.py", line 1075, in read
    first_packet = self.connection._read_packet()
  File "/home/moluo/.virtualenvs/renran/lib/python3.6/site-packages/pymysql/connections.py", line 684, in _read_packet
    packet.check_error()
  File "/home/moluo/.virtualenvs/renran/lib/python3.6/site-packages/pymysql/protocol.py", line 220, in check_error
    err.raise_mysql_exception(self._data)
  File "/home/moluo/.virtualenvs/renran/lib/python3.6/site-packages/pymysql/err.py", line 109, in raise_mysql_exception
    raise errorclass(errno, errval)
pymysql.err.ProgrammingError: (1146, "Table 'renran.xadmin_usersettings' doesn't exist")

The above exception was the direct cause of the following exception:

Traceback (most recent call last):
  File "/home/moluo/.virtualenvs/renran/lib/python3.6/site-packages/django/core/handlers/exception.py", line 34, in inner
    response = get_response(request)
  File "/home/moluo/.virtualenvs/renran/lib/python3.6/site-packages/django/core/handlers/base.py", line 115, in _get_response
    response = self.process_exception_by_middleware(e, request)
  File "/home/moluo/.virtualenvs/renran/lib/python3.6/site-packages/django/core/handlers/base.py", line 113, in _get_response
    response = wrapped_callback(request, *callback_args, **callback_kwargs)
  File "/home/moluo/.virtualenvs/renran/lib/python3.6/site-packages/xadmin/sites.py", line 300, in wrapper
    return self.admin_view(view, cacheable)(*args, **kwargs)
  File "/home/moluo/.virtualenvs/renran/lib/python3.6/site-packages/django/views/decorators/cache.py", line 44, in _wrapped_view_func
    response = view_func(request, *args, **kwargs)
  File "/home/moluo/.virtualenvs/renran/lib/python3.6/site-packages/xadmin/sites.py", line 208, in inner
    return view(request, *args, **kwargs)
  File "/home/moluo/.virtualenvs/renran/lib/python3.6/site-packages/xadmin/views/base.py", line 282, in view
    return handler(request, *args, **kwargs)
  File "/home/moluo/.virtualenvs/renran/lib/python3.6/site-packages/django/views/decorators/cache.py", line 44, in _wrapped_view_func
    response = view_func(request, *args, **kwargs)
  File "/home/moluo/.virtualenvs/renran/lib/python3.6/site-packages/xadmin/views/dashboard.py", line 592, in get
    self.widgets = self.get_widgets()
  File "/home/moluo/.virtualenvs/renran/lib/python3.6/site-packages/xadmin/views/base.py", line 80, in method
    return filter_chain(filters, len(filters) - 1, _inner_method, *args, **kwargs)
  File "/home/moluo/.virtualenvs/renran/lib/python3.6/site-packages/xadmin/views/base.py", line 49, in filter_chain
    return func()
  File "/home/moluo/.virtualenvs/renran/lib/python3.6/site-packages/xadmin/views/base.py", line 74, in _inner_method
    return func(self, *args, **kwargs)
  File "/home/moluo/.virtualenvs/renran/lib/python3.6/site-packages/xadmin/views/dashboard.py", line 549, in get_widgets
    if len(portal_pos):
  File "/home/moluo/.virtualenvs/renran/lib/python3.6/site-packages/django/db/models/query.py", line 256, in __len__
    self._fetch_all()
  File "/home/moluo/.virtualenvs/renran/lib/python3.6/site-packages/django/db/models/query.py", line 1242, in _fetch_all
    self._result_cache = list(self._iterable_class(self))
  File "/home/moluo/.virtualenvs/renran/lib/python3.6/site-packages/django/db/models/query.py", line 55, in __iter__
    results = compiler.execute_sql(chunked_fetch=self.chunked_fetch, chunk_size=self.chunk_size)
  File "/home/moluo/.virtualenvs/renran/lib/python3.6/site-packages/django/db/models/sql/compiler.py", line 1097, in execute_sql
    cursor.execute(sql, params)
  File "/home/moluo/.virtualenvs/renran/lib/python3.6/site-packages/django/db/backends/utils.py", line 99, in execute
    return super().execute(sql, params)
  File "/home/moluo/.virtualenvs/renran/lib/python3.6/site-packages/django/db/backends/utils.py", line 67, in execute
    return self._execute_with_wrappers(sql, params, many=False, executor=self._execute)
  File "/home/moluo/.virtualenvs/renran/lib/python3.6/site-packages/django/db/backends/utils.py", line 76, in _execute_with_wrappers
    return executor(sql, params, many, context)
  File "/home/moluo/.virtualenvs/renran/lib/python3.6/site-packages/django/db/backends/utils.py", line 84, in _execute
    return self.cursor.execute(sql, params)
  File "/home/moluo/.virtualenvs/renran/lib/python3.6/site-packages/django/db/utils.py", line 89, in __exit__
    raise dj_exc_value.with_traceback(traceback) from exc_value
  File "/home/moluo/.virtualenvs/renran/lib/python3.6/site-packages/django/db/backends/utils.py", line 84, in _execute
    return self.cursor.execute(sql, params)
  File "/home/moluo/.virtualenvs/renran/lib/python3.6/site-packages/django/db/backends/mysql/base.py", line 71, in execute
    return self.cursor.execute(query, args)
  File "/home/moluo/.virtualenvs/renran/lib/python3.6/site-packages/pymysql/cursors.py", line 170, in execute
    result = self._query(query)
  File "/home/moluo/.virtualenvs/renran/lib/python3.6/site-packages/pymysql/cursors.py", line 328, in _query
    conn.query(q)
  File "/home/moluo/.virtualenvs/renran/lib/python3.6/site-packages/pymysql/connections.py", line 517, in query
    self._affected_rows = self._read_query_result(unbuffered=unbuffered)
  File "/home/moluo/.virtualenvs/renran/lib/python3.6/site-packages/pymysql/connections.py", line 732, in _read_query_result
    result.read()
  File "/home/moluo/.virtualenvs/renran/lib/python3.6/site-packages/pymysql/connections.py", line 1075, in read
    first_packet = self.connection._read_packet()
  File "/home/moluo/.virtualenvs/renran/lib/python3.6/site-packages/pymysql/connections.py", line 684, in _read_packet
    packet.check_error()
  File "/home/moluo/.virtualenvs/renran/lib/python3.6/site-packages/pymysql/protocol.py", line 220, in check_error
    err.raise_mysql_exception(self._data)
  File "/home/moluo/.virtualenvs/renran/lib/python3.6/site-packages/pymysql/err.py", line 109, in raise_mysql_exception
    raise errorclass(errno, errval)
django.db.utils.ProgrammingError: (1146, "Table 'renran.xadmin_usersettings' doesn't exist")
ERROR 2020-03-02 21:43:40,674 basehttp 154 "GET /xadmin/ HTTP/1.1" 500 239385
INFO 2020-03-02 21:45:28,164 autoreload 578 Watching for file changes with StatReloader
ERROR 2020-03-02 21:45:34,318 log 228 Internal Server Error: /xadmin/
Traceback (most recent call last):
  File "/home/moluo/.virtualenvs/renran/lib/python3.6/site-packages/django/db/backends/utils.py", line 84, in _execute
    return self.cursor.execute(sql, params)
  File "/home/moluo/.virtualenvs/renran/lib/python3.6/site-packages/django/db/backends/mysql/base.py", line 71, in execute
    return self.cursor.execute(query, args)
  File "/home/moluo/.virtualenvs/renran/lib/python3.6/site-packages/pymysql/cursors.py", line 170, in execute
    result = self._query(query)
  File "/home/moluo/.virtualenvs/renran/lib/python3.6/site-packages/pymysql/cursors.py", line 328, in _query
    conn.query(q)
  File "/home/moluo/.virtualenvs/renran/lib/python3.6/site-packages/pymysql/connections.py", line 517, in query
    self._affected_rows = self._read_query_result(unbuffered=unbuffered)
  File "/home/moluo/.virtualenvs/renran/lib/python3.6/site-packages/pymysql/connections.py", line 732, in _read_query_result
    result.read()
  File "/home/moluo/.virtualenvs/renran/lib/python3.6/site-packages/pymysql/connections.py", line 1075, in read
    first_packet = self.connection._read_packet()
  File "/home/moluo/.virtualenvs/renran/lib/python3.6/site-packages/pymysql/connections.py", line 684, in _read_packet
    packet.check_error()
  File "/home/moluo/.virtualenvs/renran/lib/python3.6/site-packages/pymysql/protocol.py", line 220, in check_error
    err.raise_mysql_exception(self._data)
  File "/home/moluo/.virtualenvs/renran/lib/python3.6/site-packages/pymysql/err.py", line 109, in raise_mysql_exception
    raise errorclass(errno, errval)
pymysql.err.ProgrammingError: (1146, "Table 'renran.xadmin_usersettings' doesn't exist")

The above exception was the direct cause of the following exception:

Traceback (most recent call last):
  File "/home/moluo/.virtualenvs/renran/lib/python3.6/site-packages/django/core/handlers/exception.py", line 34, in inner
    response = get_response(request)
  File "/home/moluo/.virtualenvs/renran/lib/python3.6/site-packages/django/core/handlers/base.py", line 115, in _get_response
    response = self.process_exception_by_middleware(e, request)
  File "/home/moluo/.virtualenvs/renran/lib/python3.6/site-packages/django/core/handlers/base.py", line 113, in _get_response
    response = wrapped_callback(request, *callback_args, **callback_kwargs)
  File "/home/moluo/.virtualenvs/renran/lib/python3.6/site-packages/xadmin/sites.py", line 300, in wrapper
    return self.admin_view(view, cacheable)(*args, **kwargs)
  File "/home/moluo/.virtualenvs/renran/lib/python3.6/site-packages/django/views/decorators/cache.py", line 44, in _wrapped_view_func
    response = view_func(request, *args, **kwargs)
  File "/home/moluo/.virtualenvs/renran/lib/python3.6/site-packages/xadmin/sites.py", line 208, in inner
    return view(request, *args, **kwargs)
  File "/home/moluo/.virtualenvs/renran/lib/python3.6/site-packages/xadmin/views/base.py", line 282, in view
    return handler(request, *args, **kwargs)
  File "/home/moluo/.virtualenvs/renran/lib/python3.6/site-packages/django/views/decorators/cache.py", line 44, in _wrapped_view_func
    response = view_func(request, *args, **kwargs)
  File "/home/moluo/.virtualenvs/renran/lib/python3.6/site-packages/xadmin/views/dashboard.py", line 592, in get
    self.widgets = self.get_widgets()
  File "/home/moluo/.virtualenvs/renran/lib/python3.6/site-packages/xadmin/views/base.py", line 80, in method
    return filter_chain(filters, len(filters) - 1, _inner_method, *args, **kwargs)
  File "/home/moluo/.virtualenvs/renran/lib/python3.6/site-packages/xadmin/views/base.py", line 49, in filter_chain
    return func()
  File "/home/moluo/.virtualenvs/renran/lib/python3.6/site-packages/xadmin/views/base.py", line 74, in _inner_method
    return func(self, *args, **kwargs)
  File "/home/moluo/.virtualenvs/renran/lib/python3.6/site-packages/xadmin/views/dashboard.py", line 549, in get_widgets
    if len(portal_pos):
  File "/home/moluo/.virtualenvs/renran/lib/python3.6/site-packages/django/db/models/query.py", line 256, in __len__
    self._fetch_all()
  File "/home/moluo/.virtualenvs/renran/lib/python3.6/site-packages/django/db/models/query.py", line 1242, in _fetch_all
    self._result_cache = list(self._iterable_class(self))
  File "/home/moluo/.virtualenvs/renran/lib/python3.6/site-packages/django/db/models/query.py", line 55, in __iter__
    results = compiler.execute_sql(chunked_fetch=self.chunked_fetch, chunk_size=self.chunk_size)
  File "/home/moluo/.virtualenvs/renran/lib/python3.6/site-packages/django/db/models/sql/compiler.py", line 1097, in execute_sql
    cursor.execute(sql, params)
  File "/home/moluo/.virtualenvs/renran/lib/python3.6/site-packages/django/db/backends/utils.py", line 99, in execute
    return super().execute(sql, params)
  File "/home/moluo/.virtualenvs/renran/lib/python3.6/site-packages/django/db/backends/utils.py", line 67, in execute
    return self._execute_with_wrappers(sql, params, many=False, executor=self._execute)
  File "/home/moluo/.virtualenvs/renran/lib/python3.6/site-packages/django/db/backends/utils.py", line 76, in _execute_with_wrappers
    return executor(sql, params, many, context)
  File "/home/moluo/.virtualenvs/renran/lib/python3.6/site-packages/django/db/backends/utils.py", line 84, in _execute
    return self.cursor.execute(sql, params)
  File "/home/moluo/.virtualenvs/renran/lib/python3.6/site-packages/django/db/utils.py", line 89, in __exit__
    raise dj_exc_value.with_traceback(traceback) from exc_value
  File "/home/moluo/.virtualenvs/renran/lib/python3.6/site-packages/django/db/backends/utils.py", line 84, in _execute
    return self.cursor.execute(sql, params)
  File "/home/moluo/.virtualenvs/renran/lib/python3.6/site-packages/django/db/backends/mysql/base.py", line 71, in execute
    return self.cursor.execute(query, args)
  File "/home/moluo/.virtualenvs/renran/lib/python3.6/site-packages/pymysql/cursors.py", line 170, in execute
    result = self._query(query)
  File "/home/moluo/.virtualenvs/renran/lib/python3.6/site-packages/pymysql/cursors.py", line 328, in _query
    conn.query(q)
  File "/home/moluo/.virtualenvs/renran/lib/python3.6/site-packages/pymysql/connections.py", line 517, in query
    self._affected_rows = self._read_query_result(unbuffered=unbuffered)
  File "/home/moluo/.virtualenvs/renran/lib/python3.6/site-packages/pymysql/connections.py", line 732, in _read_query_result
    result.read()
  File "/home/moluo/.virtualenvs/renran/lib/python3.6/site-packages/pymysql/connections.py", line 1075, in read
    first_packet = self.connection._read_packet()
  File "/home/moluo/.virtualenvs/renran/lib/python3.6/site-packages/pymysql/connections.py", line 684, in _read_packet
    packet.check_error()
  File "/home/moluo/.virtualenvs/renran/lib/python3.6/site-packages/pymysql/protocol.py", line 220, in check_error
    err.raise_mysql_exception(self._data)
  File "/home/moluo/.virtualenvs/renran/lib/python3.6/site-packages/pymysql/err.py", line 109, in raise_mysql_exception
    raise errorclass(errno, errval)
django.db.utils.ProgrammingError: (1146, "Table 'renran.xadmin_usersettings' doesn't exist")
ERROR 2020-03-02 21:45:34,342 basehttp 154 "GET /xadmin/ HTTP/1.1" 500 239610
INFO 2020-03-02 21:46:23,100 autoreload 203 /home/moluo/Desktop/renran/renranapi/renranapi/apps/users/adminx.py changed, reloading.
INFO 2020-03-02 21:46:25,404 autoreload 578 Watching for file changes with StatReloader
INFO 2020-03-02 21:47:10,625 autoreload 578 Watching for file changes with StatReloader
ERROR 2020-03-02 21:47:15,200 log 228 Internal Server Error: /xadmin/
Traceback (most recent call last):
  File "/home/moluo/.virtualenvs/renran/lib/python3.6/site-packages/django/db/backends/utils.py", line 84, in _execute
    return self.cursor.execute(sql, params)
  File "/home/moluo/.virtualenvs/renran/lib/python3.6/site-packages/django/db/backends/mysql/base.py", line 71, in execute
    return self.cursor.execute(query, args)
  File "/home/moluo/.virtualenvs/renran/lib/python3.6/site-packages/pymysql/cursors.py", line 170, in execute
    result = self._query(query)
  File "/home/moluo/.virtualenvs/renran/lib/python3.6/site-packages/pymysql/cursors.py", line 328, in _query
    conn.query(q)
  File "/home/moluo/.virtualenvs/renran/lib/python3.6/site-packages/pymysql/connections.py", line 517, in query
    self._affected_rows = self._read_query_result(unbuffered=unbuffered)
  File "/home/moluo/.virtualenvs/renran/lib/python3.6/site-packages/pymysql/connections.py", line 732, in _read_query_result
    result.read()
  File "/home/moluo/.virtualenvs/renran/lib/python3.6/site-packages/pymysql/connections.py", line 1075, in read
    first_packet = self.connection._read_packet()
  File "/home/moluo/.virtualenvs/renran/lib/python3.6/site-packages/pymysql/connections.py", line 684, in _read_packet
    packet.check_error()
  File "/home/moluo/.virtualenvs/renran/lib/python3.6/site-packages/pymysql/protocol.py", line 220, in check_error
    err.raise_mysql_exception(self._data)
  File "/home/moluo/.virtualenvs/renran/lib/python3.6/site-packages/pymysql/err.py", line 109, in raise_mysql_exception
    raise errorclass(errno, errval)
pymysql.err.ProgrammingError: (1146, "Table 'renran.xadmin_usersettings' doesn't exist")

The above exception was the direct cause of the following exception:

Traceback (most recent call last):
  File "/home/moluo/.virtualenvs/renran/lib/python3.6/site-packages/django/core/handlers/exception.py", line 34, in inner
    response = get_response(request)
  File "/home/moluo/.virtualenvs/renran/lib/python3.6/site-packages/django/core/handlers/base.py", line 115, in _get_response
    response = self.process_exception_by_middleware(e, request)
  File "/home/moluo/.virtualenvs/renran/lib/python3.6/site-packages/django/core/handlers/base.py", line 113, in _get_response
    response = wrapped_callback(request, *callback_args, **callback_kwargs)
  File "/home/moluo/.virtualenvs/renran/lib/python3.6/site-packages/xadmin/sites.py", line 300, in wrapper
    return self.admin_view(view, cacheable)(*args, **kwargs)
  File "/home/moluo/.virtualenvs/renran/lib/python3.6/site-packages/django/views/decorators/cache.py", line 44, in _wrapped_view_func
    response = view_func(request, *args, **kwargs)
  File "/home/moluo/.virtualenvs/renran/lib/python3.6/site-packages/xadmin/sites.py", line 208, in inner
    return view(request, *args, **kwargs)
  File "/home/moluo/.virtualenvs/renran/lib/python3.6/site-packages/xadmin/views/base.py", line 282, in view
    return handler(request, *args, **kwargs)
  File "/home/moluo/.virtualenvs/renran/lib/python3.6/site-packages/django/views/decorators/cache.py", line 44, in _wrapped_view_func
    response = view_func(request, *args, **kwargs)
  File "/home/moluo/.virtualenvs/renran/lib/python3.6/site-packages/xadmin/views/dashboard.py", line 592, in get
    self.widgets = self.get_widgets()
  File "/home/moluo/.virtualenvs/renran/lib/python3.6/site-packages/xadmin/views/base.py", line 80, in method
    return filter_chain(filters, len(filters) - 1, _inner_method, *args, **kwargs)
  File "/home/moluo/.virtualenvs/renran/lib/python3.6/site-packages/xadmin/views/base.py", line 49, in filter_chain
    return func()
  File "/home/moluo/.virtualenvs/renran/lib/python3.6/site-packages/xadmin/views/base.py", line 74, in _inner_method
    return func(self, *args, **kwargs)
  File "/home/moluo/.virtualenvs/renran/lib/python3.6/site-packages/xadmin/views/dashboard.py", line 549, in get_widgets
    if len(portal_pos):
  File "/home/moluo/.virtualenvs/renran/lib/python3.6/site-packages/django/db/models/query.py", line 256, in __len__
    self._fetch_all()
  File "/home/moluo/.virtualenvs/renran/lib/python3.6/site-packages/django/db/models/query.py", line 1242, in _fetch_all
    self._result_cache = list(self._iterable_class(self))
  File "/home/moluo/.virtualenvs/renran/lib/python3.6/site-packages/django/db/models/query.py", line 55, in __iter__
    results = compiler.execute_sql(chunked_fetch=self.chunked_fetch, chunk_size=self.chunk_size)
  File "/home/moluo/.virtualenvs/renran/lib/python3.6/site-packages/django/db/models/sql/compiler.py", line 1097, in execute_sql
    cursor.execute(sql, params)
  File "/home/moluo/.virtualenvs/renran/lib/python3.6/site-packages/django/db/backends/utils.py", line 99, in execute
    return super().execute(sql, params)
  File "/home/moluo/.virtualenvs/renran/lib/python3.6/site-packages/django/db/backends/utils.py", line 67, in execute
    return self._execute_with_wrappers(sql, params, many=False, executor=self._execute)
  File "/home/moluo/.virtualenvs/renran/lib/python3.6/site-packages/django/db/backends/utils.py", line 76, in _execute_with_wrappers
    return executor(sql, params, many, context)
  File "/home/moluo/.virtualenvs/renran/lib/python3.6/site-packages/django/db/backends/utils.py", line 84, in _execute
    return self.cursor.execute(sql, params)
  File "/home/moluo/.virtualenvs/renran/lib/python3.6/site-packages/django/db/utils.py", line 89, in __exit__
    raise dj_exc_value.with_traceback(traceback) from exc_value
  File "/home/moluo/.virtualenvs/renran/lib/python3.6/site-packages/django/db/backends/utils.py", line 84, in _execute
    return self.cursor.execute(sql, params)
  File "/home/moluo/.virtualenvs/renran/lib/python3.6/site-packages/django/db/backends/mysql/base.py", line 71, in execute
    return self.cursor.execute(query, args)
  File "/home/moluo/.virtualenvs/renran/lib/python3.6/site-packages/pymysql/cursors.py", line 170, in execute
    result = self._query(query)
  File "/home/moluo/.virtualenvs/renran/lib/python3.6/site-packages/pymysql/cursors.py", line 328, in _query
    conn.query(q)
  File "/home/moluo/.virtualenvs/renran/lib/python3.6/site-packages/pymysql/connections.py", line 517, in query
    self._affected_rows = self._read_query_result(unbuffered=unbuffered)
  File "/home/moluo/.virtualenvs/renran/lib/python3.6/site-packages/pymysql/connections.py", line 732, in _read_query_result
    result.read()
  File "/home/moluo/.virtualenvs/renran/lib/python3.6/site-packages/pymysql/connections.py", line 1075, in read
    first_packet = self.connection._read_packet()
  File "/home/moluo/.virtualenvs/renran/lib/python3.6/site-packages/pymysql/connections.py", line 684, in _read_packet
    packet.check_error()
  File "/home/moluo/.virtualenvs/renran/lib/python3.6/site-packages/pymysql/protocol.py", line 220, in check_error
    err.raise_mysql_exception(self._data)
  File "/home/moluo/.virtualenvs/renran/lib/python3.6/site-packages/pymysql/err.py", line 109, in raise_mysql_exception
    raise errorclass(errno, errval)
django.db.utils.ProgrammingError: (1146, "Table 'renran.xadmin_usersettings' doesn't exist")
ERROR 2020-03-02 21:47:15,218 basehttp 154 "GET /xadmin/ HTTP/1.1" 500 239786
INFO 2020-03-02 21:52:59,077 autoreload 578 Watching for file changes with StatReloader
INFO 2020-03-02 21:53:38,511 autoreload 578 Watching for file changes with StatReloader
WARNING 2020-03-02 21:53:50,262 log 228 Not Found: /
WARNING 2020-03-02 21:53:50,263 basehttp 154 "GET / HTTP/1.1" 404 2035
WARNING 2020-03-02 21:53:51,893 log 228 Not Found: /favicon.ico
WARNING 2020-03-02 21:53:51,895 basehttp 154 "GET /favicon.ico HTTP/1.1" 404 2086
ERROR 2020-03-02 21:53:58,431 log 228 Internal Server Error: /xadmin/
Traceback (most recent call last):
  File "/home/moluo/.virtualenvs/renran/lib/python3.6/site-packages/django/db/backends/utils.py", line 84, in _execute
    return self.cursor.execute(sql, params)
  File "/home/moluo/.virtualenvs/renran/lib/python3.6/site-packages/django/db/backends/mysql/base.py", line 71, in execute
    return self.cursor.execute(query, args)
  File "/home/moluo/.virtualenvs/renran/lib/python3.6/site-packages/pymysql/cursors.py", line 170, in execute
    result = self._query(query)
  File "/home/moluo/.virtualenvs/renran/lib/python3.6/site-packages/pymysql/cursors.py", line 328, in _query
    conn.query(q)
  File "/home/moluo/.virtualenvs/renran/lib/python3.6/site-packages/pymysql/connections.py", line 517, in query
    self._affected_rows = self._read_query_result(unbuffered=unbuffered)
  File "/home/moluo/.virtualenvs/renran/lib/python3.6/site-packages/pymysql/connections.py", line 732, in _read_query_result
    result.read()
  File "/home/moluo/.virtualenvs/renran/lib/python3.6/site-packages/pymysql/connections.py", line 1075, in read
    first_packet = self.connection._read_packet()
  File "/home/moluo/.virtualenvs/renran/lib/python3.6/site-packages/pymysql/connections.py", line 684, in _read_packet
    packet.check_error()
  File "/home/moluo/.virtualenvs/renran/lib/python3.6/site-packages/pymysql/protocol.py", line 220, in check_error
    err.raise_mysql_exception(self._data)
  File "/home/moluo/.virtualenvs/renran/lib/python3.6/site-packages/pymysql/err.py", line 109, in raise_mysql_exception
    raise errorclass(errno, errval)
pymysql.err.ProgrammingError: (1146, "Table 'renran.xadmin_usersettings' doesn't exist")

The above exception was the direct cause of the following exception:

Traceback (most recent call last):
  File "/home/moluo/.virtualenvs/renran/lib/python3.6/site-packages/django/core/handlers/exception.py", line 34, in inner
    response = get_response(request)
  File "/home/moluo/.virtualenvs/renran/lib/python3.6/site-packages/django/core/handlers/base.py", line 115, in _get_response
    response = self.process_exception_by_middleware(e, request)
  File "/home/moluo/.virtualenvs/renran/lib/python3.6/site-packages/django/core/handlers/base.py", line 113, in _get_response
    response = wrapped_callback(request, *callback_args, **callback_kwargs)
  File "/home/moluo/.virtualenvs/renran/lib/python3.6/site-packages/xadmin/sites.py", line 300, in wrapper
    return self.admin_view(view, cacheable)(*args, **kwargs)
  File "/home/moluo/.virtualenvs/renran/lib/python3.6/site-packages/django/views/decorators/cache.py", line 44, in _wrapped_view_func
    response = view_func(request, *args, **kwargs)
  File "/home/moluo/.virtualenvs/renran/lib/python3.6/site-packages/xadmin/sites.py", line 208, in inner
    return view(request, *args, **kwargs)
  File "/home/moluo/.virtualenvs/renran/lib/python3.6/site-packages/xadmin/views/base.py", line 282, in view
    return handler(request, *args, **kwargs)
  File "/home/moluo/.virtualenvs/renran/lib/python3.6/site-packages/django/views/decorators/cache.py", line 44, in _wrapped_view_func
    response = view_func(request, *args, **kwargs)
  File "/home/moluo/.virtualenvs/renran/lib/python3.6/site-packages/xadmin/views/dashboard.py", line 592, in get
    self.widgets = self.get_widgets()
  File "/home/moluo/.virtualenvs/renran/lib/python3.6/site-packages/xadmin/views/base.py", line 80, in method
    return filter_chain(filters, len(filters) - 1, _inner_method, *args, **kwargs)
  File "/home/moluo/.virtualenvs/renran/lib/python3.6/site-packages/xadmin/views/base.py", line 49, in filter_chain
    return func()
  File "/home/moluo/.virtualenvs/renran/lib/python3.6/site-packages/xadmin/views/base.py", line 74, in _inner_method
    return func(self, *args, **kwargs)
  File "/home/moluo/.virtualenvs/renran/lib/python3.6/site-packages/xadmin/views/dashboard.py", line 549, in get_widgets
    if len(portal_pos):
  File "/home/moluo/.virtualenvs/renran/lib/python3.6/site-packages/django/db/models/query.py", line 256, in __len__
    self._fetch_all()
  File "/home/moluo/.virtualenvs/renran/lib/python3.6/site-packages/django/db/models/query.py", line 1242, in _fetch_all
    self._result_cache = list(self._iterable_class(self))
  File "/home/moluo/.virtualenvs/renran/lib/python3.6/site-packages/django/db/models/query.py", line 55, in __iter__
    results = compiler.execute_sql(chunked_fetch=self.chunked_fetch, chunk_size=self.chunk_size)
  File "/home/moluo/.virtualenvs/renran/lib/python3.6/site-packages/django/db/models/sql/compiler.py", line 1097, in execute_sql
    cursor.execute(sql, params)
  File "/home/moluo/.virtualenvs/renran/lib/python3.6/site-packages/django/db/backends/utils.py", line 99, in execute
    return super().execute(sql, params)
  File "/home/moluo/.virtualenvs/renran/lib/python3.6/site-packages/django/db/backends/utils.py", line 67, in execute
    return self._execute_with_wrappers(sql, params, many=False, executor=self._execute)
  File "/home/moluo/.virtualenvs/renran/lib/python3.6/site-packages/django/db/backends/utils.py", line 76, in _execute_with_wrappers
    return executor(sql, params, many, context)
  File "/home/moluo/.virtualenvs/renran/lib/python3.6/site-packages/django/db/backends/utils.py", line 84, in _execute
    return self.cursor.execute(sql, params)
  File "/home/moluo/.virtualenvs/renran/lib/python3.6/site-packages/django/db/utils.py", line 89, in __exit__
    raise dj_exc_value.with_traceback(traceback) from exc_value
  File "/home/moluo/.virtualenvs/renran/lib/python3.6/site-packages/django/db/backends/utils.py", line 84, in _execute
    return self.cursor.execute(sql, params)
  File "/home/moluo/.virtualenvs/renran/lib/python3.6/site-packages/django/db/backends/mysql/base.py", line 71, in execute
    return self.cursor.execute(query, args)
  File "/home/moluo/.virtualenvs/renran/lib/python3.6/site-packages/pymysql/cursors.py", line 170, in execute
    result = self._query(query)
  File "/home/moluo/.virtualenvs/renran/lib/python3.6/site-packages/pymysql/cursors.py", line 328, in _query
    conn.query(q)
  File "/home/moluo/.virtualenvs/renran/lib/python3.6/site-packages/pymysql/connections.py", line 517, in query
    self._affected_rows = self._read_query_result(unbuffered=unbuffered)
  File "/home/moluo/.virtualenvs/renran/lib/python3.6/site-packages/pymysql/connections.py", line 732, in _read_query_result
    result.read()
  File "/home/moluo/.virtualenvs/renran/lib/python3.6/site-packages/pymysql/connections.py", line 1075, in read
    first_packet = self.connection._read_packet()
  File "/home/moluo/.virtualenvs/renran/lib/python3.6/site-packages/pymysql/connections.py", line 684, in _read_packet
    packet.check_error()
  File "/home/moluo/.virtualenvs/renran/lib/python3.6/site-packages/pymysql/protocol.py", line 220, in check_error
    err.raise_mysql_exception(self._data)
  File "/home/moluo/.virtualenvs/renran/lib/python3.6/site-packages/pymysql/err.py", line 109, in raise_mysql_exception
    raise errorclass(errno, errval)
django.db.utils.ProgrammingError: (1146, "Table 'renran.xadmin_usersettings' doesn't exist")
ERROR 2020-03-02 21:53:58,436 basehttp 154 "GET /xadmin/ HTTP/1.1" 500 239651
ERROR 2020-03-02 21:54:03,053 log 228 Internal Server Error: /xadmin/
Traceback (most recent call last):
  File "/home/moluo/.virtualenvs/renran/lib/python3.6/site-packages/django/db/backends/utils.py", line 84, in _execute
    return self.cursor.execute(sql, params)
  File "/home/moluo/.virtualenvs/renran/lib/python3.6/site-packages/django/db/backends/mysql/base.py", line 71, in execute
    return self.cursor.execute(query, args)
  File "/home/moluo/.virtualenvs/renran/lib/python3.6/site-packages/pymysql/cursors.py", line 170, in execute
    result = self._query(query)
  File "/home/moluo/.virtualenvs/renran/lib/python3.6/site-packages/pymysql/cursors.py", line 328, in _query
    conn.query(q)
  File "/home/moluo/.virtualenvs/renran/lib/python3.6/site-packages/pymysql/connections.py", line 517, in query
    self._affected_rows = self._read_query_result(unbuffered=unbuffered)
  File "/home/moluo/.virtualenvs/renran/lib/python3.6/site-packages/pymysql/connections.py", line 732, in _read_query_result
    result.read()
  File "/home/moluo/.virtualenvs/renran/lib/python3.6/site-packages/pymysql/connections.py", line 1075, in read
    first_packet = self.connection._read_packet()
  File "/home/moluo/.virtualenvs/renran/lib/python3.6/site-packages/pymysql/connections.py", line 684, in _read_packet
    packet.check_error()
  File "/home/moluo/.virtualenvs/renran/lib/python3.6/site-packages/pymysql/protocol.py", line 220, in check_error
    err.raise_mysql_exception(self._data)
  File "/home/moluo/.virtualenvs/renran/lib/python3.6/site-packages/pymysql/err.py", line 109, in raise_mysql_exception
    raise errorclass(errno, errval)
pymysql.err.ProgrammingError: (1146, "Table 'renran.xadmin_usersettings' doesn't exist")

The above exception was the direct cause of the following exception:

Traceback (most recent call last):
  File "/home/moluo/.virtualenvs/renran/lib/python3.6/site-packages/django/core/handlers/exception.py", line 34, in inner
    response = get_response(request)
  File "/home/moluo/.virtualenvs/renran/lib/python3.6/site-packages/django/core/handlers/base.py", line 115, in _get_response
    response = self.process_exception_by_middleware(e, request)
  File "/home/moluo/.virtualenvs/renran/lib/python3.6/site-packages/django/core/handlers/base.py", line 113, in _get_response
    response = wrapped_callback(request, *callback_args, **callback_kwargs)
  File "/home/moluo/.virtualenvs/renran/lib/python3.6/site-packages/xadmin/sites.py", line 300, in wrapper
    return self.admin_view(view, cacheable)(*args, **kwargs)
  File "/home/moluo/.virtualenvs/renran/lib/python3.6/site-packages/django/views/decorators/cache.py", line 44, in _wrapped_view_func
    response = view_func(request, *args, **kwargs)
  File "/home/moluo/.virtualenvs/renran/lib/python3.6/site-packages/xadmin/sites.py", line 208, in inner
    return view(request, *args, **kwargs)
  File "/home/moluo/.virtualenvs/renran/lib/python3.6/site-packages/xadmin/views/base.py", line 282, in view
    return handler(request, *args, **kwargs)
  File "/home/moluo/.virtualenvs/renran/lib/python3.6/site-packages/django/views/decorators/cache.py", line 44, in _wrapped_view_func
    response = view_func(request, *args, **kwargs)
  File "/home/moluo/.virtualenvs/renran/lib/python3.6/site-packages/xadmin/views/dashboard.py", line 592, in get
    self.widgets = self.get_widgets()
  File "/home/moluo/.virtualenvs/renran/lib/python3.6/site-packages/xadmin/views/base.py", line 80, in method
    return filter_chain(filters, len(filters) - 1, _inner_method, *args, **kwargs)
  File "/home/moluo/.virtualenvs/renran/lib/python3.6/site-packages/xadmin/views/base.py", line 49, in filter_chain
    return func()
  File "/home/moluo/.virtualenvs/renran/lib/python3.6/site-packages/xadmin/views/base.py", line 74, in _inner_method
    return func(self, *args, **kwargs)
  File "/home/moluo/.virtualenvs/renran/lib/python3.6/site-packages/xadmin/views/dashboard.py", line 549, in get_widgets
    if len(portal_pos):
  File "/home/moluo/.virtualenvs/renran/lib/python3.6/site-packages/django/db/models/query.py", line 256, in __len__
    self._fetch_all()
  File "/home/moluo/.virtualenvs/renran/lib/python3.6/site-packages/django/db/models/query.py", line 1242, in _fetch_all
    self._result_cache = list(self._iterable_class(self))
  File "/home/moluo/.virtualenvs/renran/lib/python3.6/site-packages/django/db/models/query.py", line 55, in __iter__
    results = compiler.execute_sql(chunked_fetch=self.chunked_fetch, chunk_size=self.chunk_size)
  File "/home/moluo/.virtualenvs/renran/lib/python3.6/site-packages/django/db/models/sql/compiler.py", line 1097, in execute_sql
    cursor.execute(sql, params)
  File "/home/moluo/.virtualenvs/renran/lib/python3.6/site-packages/django/db/backends/utils.py", line 99, in execute
    return super().execute(sql, params)
  File "/home/moluo/.virtualenvs/renran/lib/python3.6/site-packages/django/db/backends/utils.py", line 67, in execute
    return self._execute_with_wrappers(sql, params, many=False, executor=self._execute)
  File "/home/moluo/.virtualenvs/renran/lib/python3.6/site-packages/django/db/backends/utils.py", line 76, in _execute_with_wrappers
    return executor(sql, params, many, context)
  File "/home/moluo/.virtualenvs/renran/lib/python3.6/site-packages/django/db/backends/utils.py", line 84, in _execute
    return self.cursor.execute(sql, params)
  File "/home/moluo/.virtualenvs/renran/lib/python3.6/site-packages/django/db/utils.py", line 89, in __exit__
    raise dj_exc_value.with_traceback(traceback) from exc_value
  File "/home/moluo/.virtualenvs/renran/lib/python3.6/site-packages/django/db/backends/utils.py", line 84, in _execute
    return self.cursor.execute(sql, params)
  File "/home/moluo/.virtualenvs/renran/lib/python3.6/site-packages/django/db/backends/mysql/base.py", line 71, in execute
    return self.cursor.execute(query, args)
  File "/home/moluo/.virtualenvs/renran/lib/python3.6/site-packages/pymysql/cursors.py", line 170, in execute
    result = self._query(query)
  File "/home/moluo/.virtualenvs/renran/lib/python3.6/site-packages/pymysql/cursors.py", line 328, in _query
    conn.query(q)
  File "/home/moluo/.virtualenvs/renran/lib/python3.6/site-packages/pymysql/connections.py", line 517, in query
    self._affected_rows = self._read_query_result(unbuffered=unbuffered)
  File "/home/moluo/.virtualenvs/renran/lib/python3.6/site-packages/pymysql/connections.py", line 732, in _read_query_result
    result.read()
  File "/home/moluo/.virtualenvs/renran/lib/python3.6/site-packages/pymysql/connections.py", line 1075, in read
    first_packet = self.connection._read_packet()
  File "/home/moluo/.virtualenvs/renran/lib/python3.6/site-packages/pymysql/connections.py", line 684, in _read_packet
    packet.check_error()
  File "/home/moluo/.virtualenvs/renran/lib/python3.6/site-packages/pymysql/protocol.py", line 220, in check_error
    err.raise_mysql_exception(self._data)
  File "/home/moluo/.virtualenvs/renran/lib/python3.6/site-packages/pymysql/err.py", line 109, in raise_mysql_exception
    raise errorclass(errno, errval)
django.db.utils.ProgrammingError: (1146, "Table 'renran.xadmin_usersettings' doesn't exist")
ERROR 2020-03-02 21:54:03,058 basehttp 154 "GET /xadmin/ HTTP/1.1" 500 239784
INFO 2020-03-02 21:55:01,612 autoreload 578 Watching for file changes with StatReloader
ERROR 2020-03-02 21:55:17,969 log 228 Internal Server Error: /xadmin/
Traceback (most recent call last):
  File "/home/moluo/.virtualenvs/renran/lib/python3.6/site-packages/django/db/backends/utils.py", line 84, in _execute
    return self.cursor.execute(sql, params)
  File "/home/moluo/.virtualenvs/renran/lib/python3.6/site-packages/django/db/backends/mysql/base.py", line 71, in execute
    return self.cursor.execute(query, args)
  File "/home/moluo/.virtualenvs/renran/lib/python3.6/site-packages/pymysql/cursors.py", line 170, in execute
    result = self._query(query)
  File "/home/moluo/.virtualenvs/renran/lib/python3.6/site-packages/pymysql/cursors.py", line 328, in _query
    conn.query(q)
  File "/home/moluo/.virtualenvs/renran/lib/python3.6/site-packages/pymysql/connections.py", line 517, in query
    self._affected_rows = self._read_query_result(unbuffered=unbuffered)
  File "/home/moluo/.virtualenvs/renran/lib/python3.6/site-packages/pymysql/connections.py", line 732, in _read_query_result
    result.read()
  File "/home/moluo/.virtualenvs/renran/lib/python3.6/site-packages/pymysql/connections.py", line 1075, in read
    first_packet = self.connection._read_packet()
  File "/home/moluo/.virtualenvs/renran/lib/python3.6/site-packages/pymysql/connections.py", line 684, in _read_packet
    packet.check_error()
  File "/home/moluo/.virtualenvs/renran/lib/python3.6/site-packages/pymysql/protocol.py", line 220, in check_error
    err.raise_mysql_exception(self._data)
  File "/home/moluo/.virtualenvs/renran/lib/python3.6/site-packages/pymysql/err.py", line 109, in raise_mysql_exception
    raise errorclass(errno, errval)
pymysql.err.ProgrammingError: (1146, "Table 'renran.xadmin_usersettings' doesn't exist")

The above exception was the direct cause of the following exception:

Traceback (most recent call last):
  File "/home/moluo/.virtualenvs/renran/lib/python3.6/site-packages/django/core/handlers/exception.py", line 34, in inner
    response = get_response(request)
  File "/home/moluo/.virtualenvs/renran/lib/python3.6/site-packages/django/core/handlers/base.py", line 115, in _get_response
    response = self.process_exception_by_middleware(e, request)
  File "/home/moluo/.virtualenvs/renran/lib/python3.6/site-packages/django/core/handlers/base.py", line 113, in _get_response
    response = wrapped_callback(request, *callback_args, **callback_kwargs)
  File "/home/moluo/.virtualenvs/renran/lib/python3.6/site-packages/xadmin/sites.py", line 300, in wrapper
    return self.admin_view(view, cacheable)(*args, **kwargs)
  File "/home/moluo/.virtualenvs/renran/lib/python3.6/site-packages/django/views/decorators/cache.py", line 44, in _wrapped_view_func
    response = view_func(request, *args, **kwargs)
  File "/home/moluo/.virtualenvs/renran/lib/python3.6/site-packages/xadmin/sites.py", line 208, in inner
    return view(request, *args, **kwargs)
  File "/home/moluo/.virtualenvs/renran/lib/python3.6/site-packages/xadmin/views/base.py", line 282, in view
    return handler(request, *args, **kwargs)
  File "/home/moluo/.virtualenvs/renran/lib/python3.6/site-packages/django/views/decorators/cache.py", line 44, in _wrapped_view_func
    response = view_func(request, *args, **kwargs)
  File "/home/moluo/.virtualenvs/renran/lib/python3.6/site-packages/xadmin/views/dashboard.py", line 592, in get
    self.widgets = self.get_widgets()
  File "/home/moluo/.virtualenvs/renran/lib/python3.6/site-packages/xadmin/views/base.py", line 80, in method
    return filter_chain(filters, len(filters) - 1, _inner_method, *args, **kwargs)
  File "/home/moluo/.virtualenvs/renran/lib/python3.6/site-packages/xadmin/views/base.py", line 49, in filter_chain
    return func()
  File "/home/moluo/.virtualenvs/renran/lib/python3.6/site-packages/xadmin/views/base.py", line 74, in _inner_method
    return func(self, *args, **kwargs)
  File "/home/moluo/.virtualenvs/renran/lib/python3.6/site-packages/xadmin/views/dashboard.py", line 549, in get_widgets
    if len(portal_pos):
  File "/home/moluo/.virtualenvs/renran/lib/python3.6/site-packages/django/db/models/query.py", line 256, in __len__
    self._fetch_all()
  File "/home/moluo/.virtualenvs/renran/lib/python3.6/site-packages/django/db/models/query.py", line 1242, in _fetch_all
    self._result_cache = list(self._iterable_class(self))
  File "/home/moluo/.virtualenvs/renran/lib/python3.6/site-packages/django/db/models/query.py", line 55, in __iter__
    results = compiler.execute_sql(chunked_fetch=self.chunked_fetch, chunk_size=self.chunk_size)
  File "/home/moluo/.virtualenvs/renran/lib/python3.6/site-packages/django/db/models/sql/compiler.py", line 1097, in execute_sql
    cursor.execute(sql, params)
  File "/home/moluo/.virtualenvs/renran/lib/python3.6/site-packages/django/db/backends/utils.py", line 99, in execute
    return super().execute(sql, params)
  File "/home/moluo/.virtualenvs/renran/lib/python3.6/site-packages/django/db/backends/utils.py", line 67, in execute
    return self._execute_with_wrappers(sql, params, many=False, executor=self._execute)
  File "/home/moluo/.virtualenvs/renran/lib/python3.6/site-packages/django/db/backends/utils.py", line 76, in _execute_with_wrappers
    return executor(sql, params, many, context)
  File "/home/moluo/.virtualenvs/renran/lib/python3.6/site-packages/django/db/backends/utils.py", line 84, in _execute
    return self.cursor.execute(sql, params)
  File "/home/moluo/.virtualenvs/renran/lib/python3.6/site-packages/django/db/utils.py", line 89, in __exit__
    raise dj_exc_value.with_traceback(traceback) from exc_value
  File "/home/moluo/.virtualenvs/renran/lib/python3.6/site-packages/django/db/backends/utils.py", line 84, in _execute
    return self.cursor.execute(sql, params)
  File "/home/moluo/.virtualenvs/renran/lib/python3.6/site-packages/django/db/backends/mysql/base.py", line 71, in execute
    return self.cursor.execute(query, args)
  File "/home/moluo/.virtualenvs/renran/lib/python3.6/site-packages/pymysql/cursors.py", line 170, in execute
    result = self._query(query)
  File "/home/moluo/.virtualenvs/renran/lib/python3.6/site-packages/pymysql/cursors.py", line 328, in _query
    conn.query(q)
  File "/home/moluo/.virtualenvs/renran/lib/python3.6/site-packages/pymysql/connections.py", line 517, in query
    self._affected_rows = self._read_query_result(unbuffered=unbuffered)
  File "/home/moluo/.virtualenvs/renran/lib/python3.6/site-packages/pymysql/connections.py", line 732, in _read_query_result
    result.read()
  File "/home/moluo/.virtualenvs/renran/lib/python3.6/site-packages/pymysql/connections.py", line 1075, in read
    first_packet = self.connection._read_packet()
  File "/home/moluo/.virtualenvs/renran/lib/python3.6/site-packages/pymysql/connections.py", line 684, in _read_packet
    packet.check_error()
  File "/home/moluo/.virtualenvs/renran/lib/python3.6/site-packages/pymysql/protocol.py", line 220, in check_error
    err.raise_mysql_exception(self._data)
  File "/home/moluo/.virtualenvs/renran/lib/python3.6/site-packages/pymysql/err.py", line 109, in raise_mysql_exception
    raise errorclass(errno, errval)
django.db.utils.ProgrammingError: (1146, "Table 'renran.xadmin_usersettings' doesn't exist")
ERROR 2020-03-02 21:55:18,040 basehttp 154 "GET /xadmin/ HTTP/1.1" 500 239785
INFO 2020-03-02 21:57:30,050 autoreload 578 Watching for file changes with StatReloader
INFO 2020-03-02 21:59:29,961 autoreload 578 Watching for file changes with StatReloader
ERROR 2020-03-02 21:59:34,683 log 228 Internal Server Error: /xadmin/
Traceback (most recent call last):
  File "/home/moluo/.virtualenvs/renran/lib/python3.6/site-packages/django/db/backends/utils.py", line 84, in _execute
    return self.cursor.execute(sql, params)
  File "/home/moluo/.virtualenvs/renran/lib/python3.6/site-packages/django/db/backends/mysql/base.py", line 71, in execute
    return self.cursor.execute(query, args)
  File "/home/moluo/.virtualenvs/renran/lib/python3.6/site-packages/pymysql/cursors.py", line 170, in execute
    result = self._query(query)
  File "/home/moluo/.virtualenvs/renran/lib/python3.6/site-packages/pymysql/cursors.py", line 328, in _query
    conn.query(q)
  File "/home/moluo/.virtualenvs/renran/lib/python3.6/site-packages/pymysql/connections.py", line 517, in query
    self._affected_rows = self._read_query_result(unbuffered=unbuffered)
  File "/home/moluo/.virtualenvs/renran/lib/python3.6/site-packages/pymysql/connections.py", line 732, in _read_query_result
    result.read()
  File "/home/moluo/.virtualenvs/renran/lib/python3.6/site-packages/pymysql/connections.py", line 1075, in read
    first_packet = self.connection._read_packet()
  File "/home/moluo/.virtualenvs/renran/lib/python3.6/site-packages/pymysql/connections.py", line 684, in _read_packet
    packet.check_error()
  File "/home/moluo/.virtualenvs/renran/lib/python3.6/site-packages/pymysql/protocol.py", line 220, in check_error
    err.raise_mysql_exception(self._data)
  File "/home/moluo/.virtualenvs/renran/lib/python3.6/site-packages/pymysql/err.py", line 109, in raise_mysql_exception
    raise errorclass(errno, errval)
pymysql.err.ProgrammingError: (1146, "Table 'renran.xadmin_usersettings' doesn't exist")

The above exception was the direct cause of the following exception:

Traceback (most recent call last):
  File "/home/moluo/.virtualenvs/renran/lib/python3.6/site-packages/django/core/handlers/exception.py", line 34, in inner
    response = get_response(request)
  File "/home/moluo/.virtualenvs/renran/lib/python3.6/site-packages/django/core/handlers/base.py", line 115, in _get_response
    response = self.process_exception_by_middleware(e, request)
  File "/home/moluo/.virtualenvs/renran/lib/python3.6/site-packages/django/core/handlers/base.py", line 113, in _get_response
    response = wrapped_callback(request, *callback_args, **callback_kwargs)
  File "/home/moluo/.virtualenvs/renran/lib/python3.6/site-packages/xadmin/sites.py", line 300, in wrapper
    return self.admin_view(view, cacheable)(*args, **kwargs)
  File "/home/moluo/.virtualenvs/renran/lib/python3.6/site-packages/django/views/decorators/cache.py", line 44, in _wrapped_view_func
    response = view_func(request, *args, **kwargs)
  File "/home/moluo/.virtualenvs/renran/lib/python3.6/site-packages/xadmin/sites.py", line 208, in inner
    return view(request, *args, **kwargs)
  File "/home/moluo/.virtualenvs/renran/lib/python3.6/site-packages/xadmin/views/base.py", line 282, in view
    return handler(request, *args, **kwargs)
  File "/home/moluo/.virtualenvs/renran/lib/python3.6/site-packages/django/views/decorators/cache.py", line 44, in _wrapped_view_func
    response = view_func(request, *args, **kwargs)
  File "/home/moluo/.virtualenvs/renran/lib/python3.6/site-packages/xadmin/views/dashboard.py", line 592, in get
    self.widgets = self.get_widgets()
  File "/home/moluo/.virtualenvs/renran/lib/python3.6/site-packages/xadmin/views/base.py", line 80, in method
    return filter_chain(filters, len(filters) - 1, _inner_method, *args, **kwargs)
  File "/home/moluo/.virtualenvs/renran/lib/python3.6/site-packages/xadmin/views/base.py", line 49, in filter_chain
    return func()
  File "/home/moluo/.virtualenvs/renran/lib/python3.6/site-packages/xadmin/views/base.py", line 74, in _inner_method
    return func(self, *args, **kwargs)
  File "/home/moluo/.virtualenvs/renran/lib/python3.6/site-packages/xadmin/views/dashboard.py", line 549, in get_widgets
    if len(portal_pos):
  File "/home/moluo/.virtualenvs/renran/lib/python3.6/site-packages/django/db/models/query.py", line 256, in __len__
    self._fetch_all()
  File "/home/moluo/.virtualenvs/renran/lib/python3.6/site-packages/django/db/models/query.py", line 1242, in _fetch_all
    self._result_cache = list(self._iterable_class(self))
  File "/home/moluo/.virtualenvs/renran/lib/python3.6/site-packages/django/db/models/query.py", line 55, in __iter__
    results = compiler.execute_sql(chunked_fetch=self.chunked_fetch, chunk_size=self.chunk_size)
  File "/home/moluo/.virtualenvs/renran/lib/python3.6/site-packages/django/db/models/sql/compiler.py", line 1097, in execute_sql
    cursor.execute(sql, params)
  File "/home/moluo/.virtualenvs/renran/lib/python3.6/site-packages/django/db/backends/utils.py", line 99, in execute
    return super().execute(sql, params)
  File "/home/moluo/.virtualenvs/renran/lib/python3.6/site-packages/django/db/backends/utils.py", line 67, in execute
    return self._execute_with_wrappers(sql, params, many=False, executor=self._execute)
  File "/home/moluo/.virtualenvs/renran/lib/python3.6/site-packages/django/db/backends/utils.py", line 76, in _execute_with_wrappers
    return executor(sql, params, many, context)
  File "/home/moluo/.virtualenvs/renran/lib/python3.6/site-packages/django/db/backends/utils.py", line 84, in _execute
    return self.cursor.execute(sql, params)
  File "/home/moluo/.virtualenvs/renran/lib/python3.6/site-packages/django/db/utils.py", line 89, in __exit__
    raise dj_exc_value.with_traceback(traceback) from exc_value
  File "/home/moluo/.virtualenvs/renran/lib/python3.6/site-packages/django/db/backends/utils.py", line 84, in _execute
    return self.cursor.execute(sql, params)
  File "/home/moluo/.virtualenvs/renran/lib/python3.6/site-packages/django/db/backends/mysql/base.py", line 71, in execute
    return self.cursor.execute(query, args)
  File "/home/moluo/.virtualenvs/renran/lib/python3.6/site-packages/pymysql/cursors.py", line 170, in execute
    result = self._query(query)
  File "/home/moluo/.virtualenvs/renran/lib/python3.6/site-packages/pymysql/cursors.py", line 328, in _query
    conn.query(q)
  File "/home/moluo/.virtualenvs/renran/lib/python3.6/site-packages/pymysql/connections.py", line 517, in query
    self._affected_rows = self._read_query_result(unbuffered=unbuffered)
  File "/home/moluo/.virtualenvs/renran/lib/python3.6/site-packages/pymysql/connections.py", line 732, in _read_query_result
    result.read()
  File "/home/moluo/.virtualenvs/renran/lib/python3.6/site-packages/pymysql/connections.py", line 1075, in read
    first_packet = self.connection._read_packet()
  File "/home/moluo/.virtualenvs/renran/lib/python3.6/site-packages/pymysql/connections.py", line 684, in _read_packet
    packet.check_error()
  File "/home/moluo/.virtualenvs/renran/lib/python3.6/site-packages/pymysql/protocol.py", line 220, in check_error
    err.raise_mysql_exception(self._data)
  File "/home/moluo/.virtualenvs/renran/lib/python3.6/site-packages/pymysql/err.py", line 109, in raise_mysql_exception
    raise errorclass(errno, errval)
django.db.utils.ProgrammingError: (1146, "Table 'renran.xadmin_usersettings' doesn't exist")
ERROR 2020-03-02 21:59:34,694 basehttp 154 "GET /xadmin/ HTTP/1.1" 500 239561
ERROR 2020-03-02 21:59:41,989 log 228 Internal Server Error: /xadmin/
Traceback (most recent call last):
  File "/home/moluo/.virtualenvs/renran/lib/python3.6/site-packages/django/db/backends/utils.py", line 84, in _execute
    return self.cursor.execute(sql, params)
  File "/home/moluo/.virtualenvs/renran/lib/python3.6/site-packages/django/db/backends/mysql/base.py", line 71, in execute
    return self.cursor.execute(query, args)
  File "/home/moluo/.virtualenvs/renran/lib/python3.6/site-packages/pymysql/cursors.py", line 170, in execute
    result = self._query(query)
  File "/home/moluo/.virtualenvs/renran/lib/python3.6/site-packages/pymysql/cursors.py", line 328, in _query
    conn.query(q)
  File "/home/moluo/.virtualenvs/renran/lib/python3.6/site-packages/pymysql/connections.py", line 517, in query
    self._affected_rows = self._read_query_result(unbuffered=unbuffered)
  File "/home/moluo/.virtualenvs/renran/lib/python3.6/site-packages/pymysql/connections.py", line 732, in _read_query_result
    result.read()
  File "/home/moluo/.virtualenvs/renran/lib/python3.6/site-packages/pymysql/connections.py", line 1075, in read
    first_packet = self.connection._read_packet()
  File "/home/moluo/.virtualenvs/renran/lib/python3.6/site-packages/pymysql/connections.py", line 684, in _read_packet
    packet.check_error()
  File "/home/moluo/.virtualenvs/renran/lib/python3.6/site-packages/pymysql/protocol.py", line 220, in check_error
    err.raise_mysql_exception(self._data)
  File "/home/moluo/.virtualenvs/renran/lib/python3.6/site-packages/pymysql/err.py", line 109, in raise_mysql_exception
    raise errorclass(errno, errval)
pymysql.err.ProgrammingError: (1146, "Table 'renran.xadmin_usersettings' doesn't exist")

The above exception was the direct cause of the following exception:

Traceback (most recent call last):
  File "/home/moluo/.virtualenvs/renran/lib/python3.6/site-packages/django/core/handlers/exception.py", line 34, in inner
    response = get_response(request)
  File "/home/moluo/.virtualenvs/renran/lib/python3.6/site-packages/django/core/handlers/base.py", line 115, in _get_response
    response = self.process_exception_by_middleware(e, request)
  File "/home/moluo/.virtualenvs/renran/lib/python3.6/site-packages/django/core/handlers/base.py", line 113, in _get_response
    response = wrapped_callback(request, *callback_args, **callback_kwargs)
  File "/home/moluo/.virtualenvs/renran/lib/python3.6/site-packages/xadmin/sites.py", line 300, in wrapper
    return self.admin_view(view, cacheable)(*args, **kwargs)
  File "/home/moluo/.virtualenvs/renran/lib/python3.6/site-packages/django/views/decorators/cache.py", line 44, in _wrapped_view_func
    response = view_func(request, *args, **kwargs)
  File "/home/moluo/.virtualenvs/renran/lib/python3.6/site-packages/xadmin/sites.py", line 208, in inner
    return view(request, *args, **kwargs)
  File "/home/moluo/.virtualenvs/renran/lib/python3.6/site-packages/xadmin/views/base.py", line 282, in view
    return handler(request, *args, **kwargs)
  File "/home/moluo/.virtualenvs/renran/lib/python3.6/site-packages/django/views/decorators/cache.py", line 44, in _wrapped_view_func
    response = view_func(request, *args, **kwargs)
  File "/home/moluo/.virtualenvs/renran/lib/python3.6/site-packages/xadmin/views/dashboard.py", line 592, in get
    self.widgets = self.get_widgets()
  File "/home/moluo/.virtualenvs/renran/lib/python3.6/site-packages/xadmin/views/base.py", line 80, in method
    return filter_chain(filters, len(filters) - 1, _inner_method, *args, **kwargs)
  File "/home/moluo/.virtualenvs/renran/lib/python3.6/site-packages/xadmin/views/base.py", line 49, in filter_chain
    return func()
  File "/home/moluo/.virtualenvs/renran/lib/python3.6/site-packages/xadmin/views/base.py", line 74, in _inner_method
    return func(self, *args, **kwargs)
  File "/home/moluo/.virtualenvs/renran/lib/python3.6/site-packages/xadmin/views/dashboard.py", line 549, in get_widgets
    if len(portal_pos):
  File "/home/moluo/.virtualenvs/renran/lib/python3.6/site-packages/django/db/models/query.py", line 256, in __len__
    self._fetch_all()
  File "/home/moluo/.virtualenvs/renran/lib/python3.6/site-packages/django/db/models/query.py", line 1242, in _fetch_all
    self._result_cache = list(self._iterable_class(self))
  File "/home/moluo/.virtualenvs/renran/lib/python3.6/site-packages/django/db/models/query.py", line 55, in __iter__
    results = compiler.execute_sql(chunked_fetch=self.chunked_fetch, chunk_size=self.chunk_size)
  File "/home/moluo/.virtualenvs/renran/lib/python3.6/site-packages/django/db/models/sql/compiler.py", line 1097, in execute_sql
    cursor.execute(sql, params)
  File "/home/moluo/.virtualenvs/renran/lib/python3.6/site-packages/django/db/backends/utils.py", line 99, in execute
    return super().execute(sql, params)
  File "/home/moluo/.virtualenvs/renran/lib/python3.6/site-packages/django/db/backends/utils.py", line 67, in execute
    return self._execute_with_wrappers(sql, params, many=False, executor=self._execute)
  File "/home/moluo/.virtualenvs/renran/lib/python3.6/site-packages/django/db/backends/utils.py", line 76, in _execute_with_wrappers
    return executor(sql, params, many, context)
  File "/home/moluo/.virtualenvs/renran/lib/python3.6/site-packages/django/db/backends/utils.py", line 84, in _execute
    return self.cursor.execute(sql, params)
  File "/home/moluo/.virtualenvs/renran/lib/python3.6/site-packages/django/db/utils.py", line 89, in __exit__
    raise dj_exc_value.with_traceback(traceback) from exc_value
  File "/home/moluo/.virtualenvs/renran/lib/python3.6/site-packages/django/db/backends/utils.py", line 84, in _execute
    return self.cursor.execute(sql, params)
  File "/home/moluo/.virtualenvs/renran/lib/python3.6/site-packages/django/db/backends/mysql/base.py", line 71, in execute
    return self.cursor.execute(query, args)
  File "/home/moluo/.virtualenvs/renran/lib/python3.6/site-packages/pymysql/cursors.py", line 170, in execute
    result = self._query(query)
  File "/home/moluo/.virtualenvs/renran/lib/python3.6/site-packages/pymysql/cursors.py", line 328, in _query
    conn.query(q)
  File "/home/moluo/.virtualenvs/renran/lib/python3.6/site-packages/pymysql/connections.py", line 517, in query
    self._affected_rows = self._read_query_result(unbuffered=unbuffered)
  File "/home/moluo/.virtualenvs/renran/lib/python3.6/site-packages/pymysql/connections.py", line 732, in _read_query_result
    result.read()
  File "/home/moluo/.virtualenvs/renran/lib/python3.6/site-packages/pymysql/connections.py", line 1075, in read
    first_packet = self.connection._read_packet()
  File "/home/moluo/.virtualenvs/renran/lib/python3.6/site-packages/pymysql/connections.py", line 684, in _read_packet
    packet.check_error()
  File "/home/moluo/.virtualenvs/renran/lib/python3.6/site-packages/pymysql/protocol.py", line 220, in check_error
    err.raise_mysql_exception(self._data)
  File "/home/moluo/.virtualenvs/renran/lib/python3.6/site-packages/pymysql/err.py", line 109, in raise_mysql_exception
    raise errorclass(errno, errval)
django.db.utils.ProgrammingError: (1146, "Table 'renran.xadmin_usersettings' doesn't exist")
ERROR 2020-03-02 21:59:41,997 basehttp 154 "GET /xadmin/ HTTP/1.1" 500 239560
INFO 2020-03-02 22:01:25,656 autoreload 578 Watching for file changes with StatReloader
ERROR 2020-03-02 22:01:59,701 log 228 Internal Server Error: /xadmin/
Traceback (most recent call last):
  File "/home/moluo/.virtualenvs/renran/lib/python3.6/site-packages/django/db/backends/utils.py", line 84, in _execute
    return self.cursor.execute(sql, params)
  File "/home/moluo/.virtualenvs/renran/lib/python3.6/site-packages/django/db/backends/mysql/base.py", line 71, in execute
    return self.cursor.execute(query, args)
  File "/home/moluo/.virtualenvs/renran/lib/python3.6/site-packages/pymysql/cursors.py", line 170, in execute
    result = self._query(query)
  File "/home/moluo/.virtualenvs/renran/lib/python3.6/site-packages/pymysql/cursors.py", line 328, in _query
    conn.query(q)
  File "/home/moluo/.virtualenvs/renran/lib/python3.6/site-packages/pymysql/connections.py", line 517, in query
    self._affected_rows = self._read_query_result(unbuffered=unbuffered)
  File "/home/moluo/.virtualenvs/renran/lib/python3.6/site-packages/pymysql/connections.py", line 732, in _read_query_result
    result.read()
  File "/home/moluo/.virtualenvs/renran/lib/python3.6/site-packages/pymysql/connections.py", line 1075, in read
    first_packet = self.connection._read_packet()
  File "/home/moluo/.virtualenvs/renran/lib/python3.6/site-packages/pymysql/connections.py", line 684, in _read_packet
    packet.check_error()
  File "/home/moluo/.virtualenvs/renran/lib/python3.6/site-packages/pymysql/protocol.py", line 220, in check_error
    err.raise_mysql_exception(self._data)
  File "/home/moluo/.virtualenvs/renran/lib/python3.6/site-packages/pymysql/err.py", line 109, in raise_mysql_exception
    raise errorclass(errno, errval)
pymysql.err.ProgrammingError: (1146, "Table 'renran.xadmin_usersettings' doesn't exist")

The above exception was the direct cause of the following exception:

Traceback (most recent call last):
  File "/home/moluo/.virtualenvs/renran/lib/python3.6/site-packages/django/core/handlers/exception.py", line 34, in inner
    response = get_response(request)
  File "/home/moluo/.virtualenvs/renran/lib/python3.6/site-packages/django/core/handlers/base.py", line 115, in _get_response
    response = self.process_exception_by_middleware(e, request)
  File "/home/moluo/.virtualenvs/renran/lib/python3.6/site-packages/django/core/handlers/base.py", line 113, in _get_response
    response = wrapped_callback(request, *callback_args, **callback_kwargs)
  File "/home/moluo/.virtualenvs/renran/lib/python3.6/site-packages/xadmin/sites.py", line 300, in wrapper
    return self.admin_view(view, cacheable)(*args, **kwargs)
  File "/home/moluo/.virtualenvs/renran/lib/python3.6/site-packages/django/views/decorators/cache.py", line 44, in _wrapped_view_func
    response = view_func(request, *args, **kwargs)
  File "/home/moluo/.virtualenvs/renran/lib/python3.6/site-packages/xadmin/sites.py", line 208, in inner
    return view(request, *args, **kwargs)
  File "/home/moluo/.virtualenvs/renran/lib/python3.6/site-packages/xadmin/views/base.py", line 282, in view
    return handler(request, *args, **kwargs)
  File "/home/moluo/.virtualenvs/renran/lib/python3.6/site-packages/django/views/decorators/cache.py", line 44, in _wrapped_view_func
    response = view_func(request, *args, **kwargs)
  File "/home/moluo/.virtualenvs/renran/lib/python3.6/site-packages/xadmin/views/dashboard.py", line 592, in get
    self.widgets = self.get_widgets()
  File "/home/moluo/.virtualenvs/renran/lib/python3.6/site-packages/xadmin/views/base.py", line 80, in method
    return filter_chain(filters, len(filters) - 1, _inner_method, *args, **kwargs)
  File "/home/moluo/.virtualenvs/renran/lib/python3.6/site-packages/xadmin/views/base.py", line 49, in filter_chain
    return func()
  File "/home/moluo/.virtualenvs/renran/lib/python3.6/site-packages/xadmin/views/base.py", line 74, in _inner_method
    return func(self, *args, **kwargs)
  File "/home/moluo/.virtualenvs/renran/lib/python3.6/site-packages/xadmin/views/dashboard.py", line 549, in get_widgets
    if len(portal_pos):
  File "/home/moluo/.virtualenvs/renran/lib/python3.6/site-packages/django/db/models/query.py", line 256, in __len__
    self._fetch_all()
  File "/home/moluo/.virtualenvs/renran/lib/python3.6/site-packages/django/db/models/query.py", line 1242, in _fetch_all
    self._result_cache = list(self._iterable_class(self))
  File "/home/moluo/.virtualenvs/renran/lib/python3.6/site-packages/django/db/models/query.py", line 55, in __iter__
    results = compiler.execute_sql(chunked_fetch=self.chunked_fetch, chunk_size=self.chunk_size)
  File "/home/moluo/.virtualenvs/renran/lib/python3.6/site-packages/django/db/models/sql/compiler.py", line 1097, in execute_sql
    cursor.execute(sql, params)
  File "/home/moluo/.virtualenvs/renran/lib/python3.6/site-packages/django/db/backends/utils.py", line 99, in execute
    return super().execute(sql, params)
  File "/home/moluo/.virtualenvs/renran/lib/python3.6/site-packages/django/db/backends/utils.py", line 67, in execute
    return self._execute_with_wrappers(sql, params, many=False, executor=self._execute)
  File "/home/moluo/.virtualenvs/renran/lib/python3.6/site-packages/django/db/backends/utils.py", line 76, in _execute_with_wrappers
    return executor(sql, params, many, context)
  File "/home/moluo/.virtualenvs/renran/lib/python3.6/site-packages/django/db/backends/utils.py", line 84, in _execute
    return self.cursor.execute(sql, params)
  File "/home/moluo/.virtualenvs/renran/lib/python3.6/site-packages/django/db/utils.py", line 89, in __exit__
    raise dj_exc_value.with_traceback(traceback) from exc_value
  File "/home/moluo/.virtualenvs/renran/lib/python3.6/site-packages/django/db/backends/utils.py", line 84, in _execute
    return self.cursor.execute(sql, params)
  File "/home/moluo/.virtualenvs/renran/lib/python3.6/site-packages/django/db/backends/mysql/base.py", line 71, in execute
    return self.cursor.execute(query, args)
  File "/home/moluo/.virtualenvs/renran/lib/python3.6/site-packages/pymysql/cursors.py", line 170, in execute
    result = self._query(query)
  File "/home/moluo/.virtualenvs/renran/lib/python3.6/site-packages/pymysql/cursors.py", line 328, in _query
    conn.query(q)
  File "/home/moluo/.virtualenvs/renran/lib/python3.6/site-packages/pymysql/connections.py", line 517, in query
    self._affected_rows = self._read_query_result(unbuffered=unbuffered)
  File "/home/moluo/.virtualenvs/renran/lib/python3.6/site-packages/pymysql/connections.py", line 732, in _read_query_result
    result.read()
  File "/home/moluo/.virtualenvs/renran/lib/python3.6/site-packages/pymysql/connections.py", line 1075, in read
    first_packet = self.connection._read_packet()
  File "/home/moluo/.virtualenvs/renran/lib/python3.6/site-packages/pymysql/connections.py", line 684, in _read_packet
    packet.check_error()
  File "/home/moluo/.virtualenvs/renran/lib/python3.6/site-packages/pymysql/protocol.py", line 220, in check_error
    err.raise_mysql_exception(self._data)
  File "/home/moluo/.virtualenvs/renran/lib/python3.6/site-packages/pymysql/err.py", line 109, in raise_mysql_exception
    raise errorclass(errno, errval)
django.db.utils.ProgrammingError: (1146, "Table 'renran.xadmin_usersettings' doesn't exist")
ERROR 2020-03-02 22:01:59,714 basehttp 154 "GET /xadmin/ HTTP/1.1" 500 239562
WARNING 2020-03-02 22:02:20,454 log 228 Not Found: /
WARNING 2020-03-02 22:02:20,456 basehttp 154 "GET / HTTP/1.1" 404 2035
ERROR 2020-03-02 22:02:27,345 log 228 Internal Server Error: /xadmin/
Traceback (most recent call last):
  File "/home/moluo/.virtualenvs/renran/lib/python3.6/site-packages/django/db/backends/utils.py", line 84, in _execute
    return self.cursor.execute(sql, params)
  File "/home/moluo/.virtualenvs/renran/lib/python3.6/site-packages/django/db/backends/mysql/base.py", line 71, in execute
    return self.cursor.execute(query, args)
  File "/home/moluo/.virtualenvs/renran/lib/python3.6/site-packages/pymysql/cursors.py", line 170, in execute
    result = self._query(query)
  File "/home/moluo/.virtualenvs/renran/lib/python3.6/site-packages/pymysql/cursors.py", line 328, in _query
    conn.query(q)
  File "/home/moluo/.virtualenvs/renran/lib/python3.6/site-packages/pymysql/connections.py", line 517, in query
    self._affected_rows = self._read_query_result(unbuffered=unbuffered)
  File "/home/moluo/.virtualenvs/renran/lib/python3.6/site-packages/pymysql/connections.py", line 732, in _read_query_result
    result.read()
  File "/home/moluo/.virtualenvs/renran/lib/python3.6/site-packages/pymysql/connections.py", line 1075, in read
    first_packet = self.connection._read_packet()
  File "/home/moluo/.virtualenvs/renran/lib/python3.6/site-packages/pymysql/connections.py", line 684, in _read_packet
    packet.check_error()
  File "/home/moluo/.virtualenvs/renran/lib/python3.6/site-packages/pymysql/protocol.py", line 220, in check_error
    err.raise_mysql_exception(self._data)
  File "/home/moluo/.virtualenvs/renran/lib/python3.6/site-packages/pymysql/err.py", line 109, in raise_mysql_exception
    raise errorclass(errno, errval)
pymysql.err.ProgrammingError: (1146, "Table 'renran.xadmin_usersettings' doesn't exist")

The above exception was the direct cause of the following exception:

Traceback (most recent call last):
  File "/home/moluo/.virtualenvs/renran/lib/python3.6/site-packages/django/core/handlers/exception.py", line 34, in inner
    response = get_response(request)
  File "/home/moluo/.virtualenvs/renran/lib/python3.6/site-packages/django/core/handlers/base.py", line 115, in _get_response
    response = self.process_exception_by_middleware(e, request)
  File "/home/moluo/.virtualenvs/renran/lib/python3.6/site-packages/django/core/handlers/base.py", line 113, in _get_response
    response = wrapped_callback(request, *callback_args, **callback_kwargs)
  File "/home/moluo/.virtualenvs/renran/lib/python3.6/site-packages/xadmin/sites.py", line 300, in wrapper
    return self.admin_view(view, cacheable)(*args, **kwargs)
  File "/home/moluo/.virtualenvs/renran/lib/python3.6/site-packages/django/views/decorators/cache.py", line 44, in _wrapped_view_func
    response = view_func(request, *args, **kwargs)
  File "/home/moluo/.virtualenvs/renran/lib/python3.6/site-packages/xadmin/sites.py", line 208, in inner
    return view(request, *args, **kwargs)
  File "/home/moluo/.virtualenvs/renran/lib/python3.6/site-packages/xadmin/views/base.py", line 282, in view
    return handler(request, *args, **kwargs)
  File "/home/moluo/.virtualenvs/renran/lib/python3.6/site-packages/django/views/decorators/cache.py", line 44, in _wrapped_view_func
    response = view_func(request, *args, **kwargs)
  File "/home/moluo/.virtualenvs/renran/lib/python3.6/site-packages/xadmin/views/dashboard.py", line 592, in get
    self.widgets = self.get_widgets()
  File "/home/moluo/.virtualenvs/renran/lib/python3.6/site-packages/xadmin/views/base.py", line 80, in method
    return filter_chain(filters, len(filters) - 1, _inner_method, *args, **kwargs)
  File "/home/moluo/.virtualenvs/renran/lib/python3.6/site-packages/xadmin/views/base.py", line 49, in filter_chain
    return func()
  File "/home/moluo/.virtualenvs/renran/lib/python3.6/site-packages/xadmin/views/base.py", line 74, in _inner_method
    return func(self, *args, **kwargs)
  File "/home/moluo/.virtualenvs/renran/lib/python3.6/site-packages/xadmin/views/dashboard.py", line 549, in get_widgets
    if len(portal_pos):
  File "/home/moluo/.virtualenvs/renran/lib/python3.6/site-packages/django/db/models/query.py", line 256, in __len__
    self._fetch_all()
  File "/home/moluo/.virtualenvs/renran/lib/python3.6/site-packages/django/db/models/query.py", line 1242, in _fetch_all
    self._result_cache = list(self._iterable_class(self))
  File "/home/moluo/.virtualenvs/renran/lib/python3.6/site-packages/django/db/models/query.py", line 55, in __iter__
    results = compiler.execute_sql(chunked_fetch=self.chunked_fetch, chunk_size=self.chunk_size)
  File "/home/moluo/.virtualenvs/renran/lib/python3.6/site-packages/django/db/models/sql/compiler.py", line 1097, in execute_sql
    cursor.execute(sql, params)
  File "/home/moluo/.virtualenvs/renran/lib/python3.6/site-packages/django/db/backends/utils.py", line 99, in execute
    return super().execute(sql, params)
  File "/home/moluo/.virtualenvs/renran/lib/python3.6/site-packages/django/db/backends/utils.py", line 67, in execute
    return self._execute_with_wrappers(sql, params, many=False, executor=self._execute)
  File "/home/moluo/.virtualenvs/renran/lib/python3.6/site-packages/django/db/backends/utils.py", line 76, in _execute_with_wrappers
    return executor(sql, params, many, context)
  File "/home/moluo/.virtualenvs/renran/lib/python3.6/site-packages/django/db/backends/utils.py", line 84, in _execute
    return self.cursor.execute(sql, params)
  File "/home/moluo/.virtualenvs/renran/lib/python3.6/site-packages/django/db/utils.py", line 89, in __exit__
    raise dj_exc_value.with_traceback(traceback) from exc_value
  File "/home/moluo/.virtualenvs/renran/lib/python3.6/site-packages/django/db/backends/utils.py", line 84, in _execute
    return self.cursor.execute(sql, params)
  File "/home/moluo/.virtualenvs/renran/lib/python3.6/site-packages/django/db/backends/mysql/base.py", line 71, in execute
    return self.cursor.execute(query, args)
  File "/home/moluo/.virtualenvs/renran/lib/python3.6/site-packages/pymysql/cursors.py", line 170, in execute
    result = self._query(query)
  File "/home/moluo/.virtualenvs/renran/lib/python3.6/site-packages/pymysql/cursors.py", line 328, in _query
    conn.query(q)
  File "/home/moluo/.virtualenvs/renran/lib/python3.6/site-packages/pymysql/connections.py", line 517, in query
    self._affected_rows = self._read_query_result(unbuffered=unbuffered)
  File "/home/moluo/.virtualenvs/renran/lib/python3.6/site-packages/pymysql/connections.py", line 732, in _read_query_result
    result.read()
  File "/home/moluo/.virtualenvs/renran/lib/python3.6/site-packages/pymysql/connections.py", line 1075, in read
    first_packet = self.connection._read_packet()
  File "/home/moluo/.virtualenvs/renran/lib/python3.6/site-packages/pymysql/connections.py", line 684, in _read_packet
    packet.check_error()
  File "/home/moluo/.virtualenvs/renran/lib/python3.6/site-packages/pymysql/protocol.py", line 220, in check_error
    err.raise_mysql_exception(self._data)
  File "/home/moluo/.virtualenvs/renran/lib/python3.6/site-packages/pymysql/err.py", line 109, in raise_mysql_exception
    raise errorclass(errno, errval)
django.db.utils.ProgrammingError: (1146, "Table 'renran.xadmin_usersettings' doesn't exist")
ERROR 2020-03-02 22:02:27,351 basehttp 154 "GET /xadmin/ HTTP/1.1" 500 239425
INFO 2020-03-02 22:06:42,031 autoreload 578 Watching for file changes with StatReloader
INFO 2020-03-02 22:06:47,913 basehttp 154 "GET /xadmin/ HTTP/1.1" 200 11579
INFO 2020-03-02 22:06:48,036 basehttp 154 "GET /static/xadmin/vendor/font-awesome/css/font-awesome.css HTTP/1.1" 304 0
INFO 2020-03-02 22:06:48,042 basehttp 154 "GET /static/xadmin/vendor/bootstrap/css/bootstrap.css HTTP/1.1" 304 0
INFO 2020-03-02 22:06:48,081 basehttp 154 "GET /static/xadmin/js/xadmin.plugin.portal.js HTTP/1.1" 200 1000
INFO 2020-03-02 22:06:48,111 basehttp 154 "GET /static/xadmin/css/xadmin.plugins.css HTTP/1.1" 304 0
INFO 2020-03-02 22:06:48,116 basehttp 154 "GET /static/xadmin/css/xadmin.page.dashboard.css HTTP/1.1" 200 790
INFO 2020-03-02 22:06:48,117 basehttp 154 "GET /static/xadmin/js/xadmin.page.dashboard.js HTTP/1.1" 200 3208
INFO 2020-03-02 22:06:48,129 basehttp 154 "GET /static/xadmin/vendor/jquery-ui/jquery.ui.effect.js HTTP/1.1" 200 31918
INFO 2020-03-02 22:06:48,137 basehttp 154 "GET /static/xadmin/css/xadmin.main.css HTTP/1.1" 304 0
INFO 2020-03-02 22:06:48,142 basehttp 154 "GET /static/xadmin/css/themes/bootstrap-xadmin.css HTTP/1.1" 304 0
INFO 2020-03-02 22:06:48,154 basehttp 154 "GET /static/xadmin/vendor/jquery/jquery.js HTTP/1.1" 304 0
INFO 2020-03-02 22:06:48,158 basehttp 154 "GET /static/xadmin/vendor/jquery-ui/jquery.ui.widget.js HTTP/1.1" 304 0
INFO 2020-03-02 22:06:48,159 basehttp 154 "GET /static/xadmin/css/xadmin.responsive.css HTTP/1.1" 304 0
INFO 2020-03-02 22:06:48,171 basehttp 154 "GET /static/xadmin/js/xadmin.plugin.themes.js HTTP/1.1" 200 3489
INFO 2020-03-02 22:06:48,175 basehttp 154 "GET /static/xadmin/vendor/jquery-ui/jquery.ui.core.js HTTP/1.1" 304 0
INFO 2020-03-02 22:06:48,184 basehttp 154 "GET /static/xadmin/vendor/jquery-ui/jquery.ui.mouse.js HTTP/1.1" 304 0
INFO 2020-03-02 22:06:48,208 basehttp 154 "GET /static/xadmin/vendor/jquery-ui/jquery.ui.sortable.js HTTP/1.1" 304 0
INFO 2020-03-02 22:06:48,210 basehttp 154 "GET /static/xadmin/vendor/bootstrap/js/bootstrap.js HTTP/1.1" 304 0
INFO 2020-03-02 22:06:48,229 basehttp 154 "GET /static/xadmin/js/xadmin.responsive.js HTTP/1.1" 304 0
INFO 2020-03-02 22:06:48,231 basehttp 154 "GET /xadmin/jsi18n/ HTTP/1.1" 200 7722
INFO 2020-03-02 22:06:48,238 basehttp 154 "GET /static/xadmin/js/xadmin.main.js HTTP/1.1" 304 0
INFO 2020-03-02 22:06:48,644 basehttp 154 "GET /static/xadmin/vendor/font-awesome/fonts/fontawesome-webfont.woff?v=4.0.3 HTTP/1.1" 304 0
INFO 2020-03-02 22:07:24,844 autoreload 203 /home/moluo/Desktop/renran/renranapi/renranapi/apps/users/adminx.py changed, reloading.
INFO 2020-03-02 22:07:26,905 autoreload 578 Watching for file changes with StatReloader
INFO 2020-03-02 22:08:23,359 autoreload 578 Watching for file changes with StatReloader
INFO 2020-03-02 22:08:39,378 autoreload 578 Watching for file changes with StatReloader
INFO 2020-03-02 22:08:52,175 autoreload 578 Watching for file changes with StatReloader
INFO 2020-03-02 22:09:00,669 basehttp 154 "GET /xadmin/ HTTP/1.1" 200 13850
INFO 2020-03-02 22:09:00,763 basehttp 154 "GET /xadmin/jsi18n/ HTTP/1.1" 200 7722
INFO 2020-03-02 22:09:05,874 basehttp 154 "POST /xadmin/settings/user HTTP/1.1" 200 0
INFO 2020-03-02 22:09:05,912 basehttp 154 "GET /static/xadmin/css/themes/bootstrap-theme.css HTTP/1.1" 200 19791
INFO 2020-03-02 22:09:53,417 basehttp 154 "POST /xadmin/settings/user HTTP/1.1" 200 0
INFO 2020-03-02 22:10:22,820 basehttp 154 "GET /xadmin/users/user/ HTTP/1.1" 200 28292
INFO 2020-03-02 22:10:22,859 basehttp 154 "GET /static/xadmin/css/xadmin.form.css HTTP/1.1" 200 3763
INFO 2020-03-02 22:10:22,894 basehttp 154 "GET /static/xadmin/js/xadmin.plugin.bookmark.js HTTP/1.1" 200 529
INFO 2020-03-02 22:10:22,903 basehttp 154 "GET /xadmin/jsi18n/ HTTP/1.1" 200 7722
INFO 2020-03-02 22:10:22,905 basehttp 154 "GET /static/xadmin/js/xadmin.plugin.details.js HTTP/1.1" 200 2319
INFO 2020-03-02 22:10:22,909 basehttp 154 "GET /static/xadmin/js/xadmin.plugin.filters.js HTTP/1.1" 200 1990
INFO 2020-03-02 22:10:22,921 basehttp 154 "GET /static/xadmin/js/xadmin.page.form.js HTTP/1.1" 200 1948
INFO 2020-03-02 22:10:22,938 basehttp 154 "GET /static/xadmin/js/xadmin.plugin.actions.js HTTP/1.1" 200 4198
INFO 2020-03-02 22:10:22,940 basehttp 154 "GET /static/xadmin/js/xadmin.page.list.js HTTP/1.1" 200 1105
INFO 2020-03-02 22:10:26,031 basehttp 154 "GET /xadmin/users/user/1/update/ HTTP/1.1" 200 30289
INFO 2020-03-02 22:10:26,082 basehttp 154 "GET /static/xadmin/vendor/bootstrap-image-gallery/css/bootstrap-image-gallery.css HTTP/1.1" 200 3339
INFO 2020-03-02 22:10:26,093 basehttp 154 "GET /static/xadmin/vendor/bootstrap-datepicker/css/datepicker.css HTTP/1.1" 200 10225
INFO 2020-03-02 22:10:26,125 basehttp 154 "GET /static/xadmin/vendor/bootstrap-clockpicker/bootstrap-clockpicker.css HTTP/1.1" 200 3729
INFO 2020-03-02 22:10:26,127 basehttp 154 "GET /static/xadmin/js/xadmin.plugin.quick-form.js HTTP/1.1" 200 7546
INFO 2020-03-02 22:10:26,130 basehttp 154 "GET /static/xadmin/vendor/load-image/load-image.js HTTP/1.1" 200 8309
INFO 2020-03-02 22:10:26,131 basehttp 154 "GET /static/xadmin/vendor/bootstrap-datepicker/js/bootstrap-datepicker.js HTTP/1.1" 200 32656
INFO 2020-03-02 22:10:26,140 basehttp 154 "GET /static/xadmin/vendor/bootstrap-image-gallery/js/bootstrap-image-gallery.js HTTP/1.1" 200 15611
INFO 2020-03-02 22:10:26,145 basehttp 154 "GET /xadmin/jsi18n/ HTTP/1.1" 200 7722
INFO 2020-03-02 22:10:26,180 basehttp 154 "GET /static/xadmin/js/xadmin.widget.datetime.js HTTP/1.1" 200 2979
INFO 2020-03-02 22:10:26,181 basehttp 154 "GET /static/xadmin/vendor/bootstrap-clockpicker/bootstrap-clockpicker.js HTTP/1.1" 200 21112
INFO 2020-03-02 22:10:31,768 basehttp 154 "GET /xadmin/xadmin/log/ HTTP/1.1" 200 28281
INFO 2020-03-02 22:10:31,829 basehttp 154 "GET /xadmin/jsi18n/ HTTP/1.1" 200 7722
INFO 2020-03-02 22:10:35,500 basehttp 154 "GET /xadmin/auth/group/ HTTP/1.1" 200 23061
INFO 2020-03-02 22:10:35,541 basehttp 154 "GET /xadmin/jsi18n/ HTTP/1.1" 200 7722
INFO 2020-03-02 22:12:32,850 basehttp 154 "GET /xadmin/users/user/ HTTP/1.1" 200 28292
INFO 2020-03-02 22:12:32,924 basehttp 154 "GET /xadmin/jsi18n/ HTTP/1.1" 200 7722
INFO 2020-03-02 22:14:39,988 basehttp 154 "OPTIONS /users/login/ HTTP/1.1" 200 0
INFO 2020-03-02 22:14:40,170 basehttp 154 "POST /users/login/ HTTP/1.1" 200 248
INFO 2020-03-02 22:14:52,563 basehttp 154 "POST /users/login/ HTTP/1.1" 200 248
INFO 2020-03-02 22:15:46,088 basehttp 154 "POST /users/login/ HTTP/1.1" 200 248
INFO 2020-03-02 22:17:59,615 basehttp 154 "POST /users/login/ HTTP/1.1" 200 248
INFO 2020-03-02 22:18:39,511 basehttp 154 "POST /users/login/ HTTP/1.1" 200 248
INFO 2020-03-03 18:32:07,671 autoreload 578 Watching for file changes with StatReloader
WARNING 2020-03-03 18:32:20,869 log 228 Not Found: /
WARNING 2020-03-03 18:32:20,873 basehttp 154 "GET / HTTP/1.1" 404 2035
WARNING 2020-03-03 18:32:21,156 log 228 Not Found: /favicon.ico
WARNING 2020-03-03 18:32:21,158 basehttp 154 "GET /favicon.ico HTTP/1.1" 404 2086
WARNING 2020-03-03 18:33:27,146 log 228 Not Found: /users/
WARNING 2020-03-03 18:33:27,153 basehttp 154 "GET /users/ HTTP/1.1" 404 2446
ERROR 2020-03-03 18:33:35,210 log 228 Internal Server Error: /users/captcha/
Traceback (most recent call last):
  File "/home/moluo/.virtualenvs/renran/lib/python3.6/site-packages/django/core/handlers/exception.py", line 34, in inner
    response = get_response(request)
  File "/home/moluo/.virtualenvs/renran/lib/python3.6/site-packages/django/core/handlers/base.py", line 145, in _get_response
    response = self.process_exception_by_middleware(e, request)
  File "/home/moluo/.virtualenvs/renran/lib/python3.6/site-packages/django/core/handlers/base.py", line 143, in _get_response
    response = response.render()
  File "/home/moluo/.virtualenvs/renran/lib/python3.6/site-packages/django/template/response.py", line 106, in render
    self.content = self.rendered_content
  File "/home/moluo/.virtualenvs/renran/lib/python3.6/site-packages/rest_framework/response.py", line 70, in rendered_content
    ret = renderer.render(self.data, accepted_media_type, context)
  File "/home/moluo/.virtualenvs/renran/lib/python3.6/site-packages/rest_framework/renderers.py", line 723, in render
    template = loader.get_template(self.template)
  File "/home/moluo/.virtualenvs/renran/lib/python3.6/site-packages/django/template/loader.py", line 19, in get_template
    raise TemplateDoesNotExist(template_name, chain=chain)
django.template.exceptions.TemplateDoesNotExist: rest_framework/api.html
ERROR 2020-03-03 18:33:35,213 basehttp 154 "GET /users/captcha/ HTTP/1.1" 500 89428
ERROR 2020-03-03 18:33:47,343 views 49 验证接口异常!15:decrypt fail
INFO 2020-03-03 18:33:47,359 basehttp 154 "POST /users/captcha/ HTTP/1.1" 200 32
INFO 2020-03-03 18:37:46,082 basehttp 154 "OPTIONS /users/captcha/ HTTP/1.1" 200 0
INFO 2020-03-03 18:37:46,427 basehttp 154 "POST /users/captcha/ HTTP/1.1" 200 33
INFO 2020-03-03 18:37:46,471 basehttp 154 "OPTIONS /users/login/ HTTP/1.1" 200 0
INFO 2020-03-03 18:37:47,006 basehttp 154 "POST /users/login/ HTTP/1.1" 200 248
INFO 2020-03-03 18:37:59,832 basehttp 154 "POST /users/captcha/ HTTP/1.1" 200 33
INFO 2020-03-03 18:37:59,980 basehttp 154 "POST /users/login/ HTTP/1.1" 200 248
INFO 2020-03-03 18:39:07,499 autoreload 203 /home/moluo/Desktop/renran/renranapi/renranapi/apps/users/views.py changed, reloading.
INFO 2020-03-03 18:39:11,877 autoreload 578 Watching for file changes with StatReloader
INFO 2020-03-03 18:45:51,458 autoreload 578 Watching for file changes with StatReloader
INFO 2020-03-03 19:03:44,297 autoreload 203 /home/moluo/Desktop/renran/renranapi/renranapi/apps/users/views.py changed, reloading.
INFO 2020-03-03 19:03:46,912 autoreload 578 Watching for file changes with StatReloader
INFO 2020-03-03 20:09:11,254 autoreload 578 Watching for file changes with StatReloader
INFO 2020-03-03 20:10:24,915 basehttp 154 "GET /users/mobile/13912345677/ HTTP/1.1" 200 31
INFO 2020-03-03 20:11:38,200 basehttp 154 "GET /users/mobile/19929238507/ HTTP/1.1" 200 31
INFO 2020-03-03 20:26:10,066 basehttp 154 "GET /users/mobile/19929238507/ HTTP/1.1" 200 31
INFO 2020-03-03 20:26:27,338 basehttp 154 "GET /users/mobile/19929238507/ HTTP/1.1" 200 31
INFO 2020-03-03 20:26:40,409 basehttp 154 "GET /users/mobile/13912345678/ HTTP/1.1" 200 31
INFO 2020-03-03 20:26:53,145 basehttp 154 "OPTIONS /users/ HTTP/1.1" 200 0
WARNING 2020-03-03 20:26:53,180 log 228 Bad Request: /users/
WARNING 2020-03-03 20:26:53,181 basehttp 154 "POST /users/ HTTP/1.1" 400 61
ERROR 2020-03-03 20:27:24,744 log 228 Internal Server Error: /users/
Traceback (most recent call last):
  File "/home/moluo/.virtualenvs/renran/lib/python3.6/site-packages/rest_framework/serializers.py", line 948, in create
    instance = ModelClass._default_manager.create(**validated_data)
  File "/home/moluo/.virtualenvs/renran/lib/python3.6/site-packages/django/db/models/manager.py", line 82, in manager_method
    return getattr(self.get_queryset(), name)(*args, **kwargs)
  File "/home/moluo/.virtualenvs/renran/lib/python3.6/site-packages/django/db/models/query.py", line 420, in create
    obj = self.model(**kwargs)
  File "/home/moluo/.virtualenvs/renran/lib/python3.6/site-packages/django/db/models/base.py", line 501, in __init__
    raise TypeError("%s() got an unexpected keyword argument '%s'" % (cls.__name__, kwarg))
TypeError: User() got an unexpected keyword argument 'sms_code'

During handling of the above exception, another exception occurred:

Traceback (most recent call last):
  File "/home/moluo/.virtualenvs/renran/lib/python3.6/site-packages/django/core/handlers/exception.py", line 34, in inner
    response = get_response(request)
  File "/home/moluo/.virtualenvs/renran/lib/python3.6/site-packages/django/core/handlers/base.py", line 115, in _get_response
    response = self.process_exception_by_middleware(e, request)
  File "/home/moluo/.virtualenvs/renran/lib/python3.6/site-packages/django/core/handlers/base.py", line 113, in _get_response
    response = wrapped_callback(request, *callback_args, **callback_kwargs)
  File "/home/moluo/.virtualenvs/renran/lib/python3.6/site-packages/django/views/decorators/csrf.py", line 54, in wrapped_view
    return view_func(*args, **kwargs)
  File "/home/moluo/.virtualenvs/renran/lib/python3.6/site-packages/django/views/generic/base.py", line 71, in view
    return self.dispatch(request, *args, **kwargs)
  File "/home/moluo/.virtualenvs/renran/lib/python3.6/site-packages/rest_framework/views.py", line 505, in dispatch
    response = self.handle_exception(exc)
  File "/home/moluo/.virtualenvs/renran/lib/python3.6/site-packages/rest_framework/views.py", line 465, in handle_exception
    self.raise_uncaught_exception(exc)
  File "/home/moluo/.virtualenvs/renran/lib/python3.6/site-packages/rest_framework/views.py", line 476, in raise_uncaught_exception
    raise exc
  File "/home/moluo/.virtualenvs/renran/lib/python3.6/site-packages/rest_framework/views.py", line 502, in dispatch
    response = handler(request, *args, **kwargs)
  File "/home/moluo/.virtualenvs/renran/lib/python3.6/site-packages/rest_framework/generics.py", line 190, in post
    return self.create(request, *args, **kwargs)
  File "/home/moluo/.virtualenvs/renran/lib/python3.6/site-packages/rest_framework/mixins.py", line 19, in create
    self.perform_create(serializer)
  File "/home/moluo/.virtualenvs/renran/lib/python3.6/site-packages/rest_framework/mixins.py", line 24, in perform_create
    serializer.save()
  File "/home/moluo/.virtualenvs/renran/lib/python3.6/site-packages/rest_framework/serializers.py", line 212, in save
    self.instance = self.create(validated_data)
  File "/home/moluo/.virtualenvs/renran/lib/python3.6/site-packages/rest_framework/serializers.py", line 967, in create
    raise TypeError(msg)
TypeError: Got a `TypeError` when calling `User.objects.create()`. This may be because you have a writable field on the serializer class that is not a valid argument to `User.objects.create()`. You may need to make the field read-only, or override the UserCreateModelSerializer.create() method to handle this correctly.
Original exception was:
 Traceback (most recent call last):
  File "/home/moluo/.virtualenvs/renran/lib/python3.6/site-packages/rest_framework/serializers.py", line 948, in create
    instance = ModelClass._default_manager.create(**validated_data)
  File "/home/moluo/.virtualenvs/renran/lib/python3.6/site-packages/django/db/models/manager.py", line 82, in manager_method
    return getattr(self.get_queryset(), name)(*args, **kwargs)
  File "/home/moluo/.virtualenvs/renran/lib/python3.6/site-packages/django/db/models/query.py", line 420, in create
    obj = self.model(**kwargs)
  File "/home/moluo/.virtualenvs/renran/lib/python3.6/site-packages/django/db/models/base.py", line 501, in __init__
    raise TypeError("%s() got an unexpected keyword argument '%s'" % (cls.__name__, kwarg))
TypeError: User() got an unexpected keyword argument 'sms_code'

ERROR 2020-03-03 20:27:24,750 basehttp 154 "POST /users/ HTTP/1.1" 500 21508
ERROR 2020-03-03 20:27:47,576 log 228 Internal Server Error: /users/
Traceback (most recent call last):
  File "/home/moluo/.virtualenvs/renran/lib/python3.6/site-packages/rest_framework/serializers.py", line 948, in create
    instance = ModelClass._default_manager.create(**validated_data)
  File "/home/moluo/.virtualenvs/renran/lib/python3.6/site-packages/django/db/models/manager.py", line 82, in manager_method
    return getattr(self.get_queryset(), name)(*args, **kwargs)
  File "/home/moluo/.virtualenvs/renran/lib/python3.6/site-packages/django/db/models/query.py", line 420, in create
    obj = self.model(**kwargs)
  File "/home/moluo/.virtualenvs/renran/lib/python3.6/site-packages/django/db/models/base.py", line 501, in __init__
    raise TypeError("%s() got an unexpected keyword argument '%s'" % (cls.__name__, kwarg))
TypeError: User() got an unexpected keyword argument 'sms_code'

During handling of the above exception, another exception occurred:

Traceback (most recent call last):
  File "/home/moluo/.virtualenvs/renran/lib/python3.6/site-packages/django/core/handlers/exception.py", line 34, in inner
    response = get_response(request)
  File "/home/moluo/.virtualenvs/renran/lib/python3.6/site-packages/django/core/handlers/base.py", line 115, in _get_response
    response = self.process_exception_by_middleware(e, request)
  File "/home/moluo/.virtualenvs/renran/lib/python3.6/site-packages/django/core/handlers/base.py", line 113, in _get_response
    response = wrapped_callback(request, *callback_args, **callback_kwargs)
  File "/home/moluo/.virtualenvs/renran/lib/python3.6/site-packages/django/views/decorators/csrf.py", line 54, in wrapped_view
    return view_func(*args, **kwargs)
  File "/home/moluo/.virtualenvs/renran/lib/python3.6/site-packages/django/views/generic/base.py", line 71, in view
    return self.dispatch(request, *args, **kwargs)
  File "/home/moluo/.virtualenvs/renran/lib/python3.6/site-packages/rest_framework/views.py", line 505, in dispatch
    response = self.handle_exception(exc)
  File "/home/moluo/.virtualenvs/renran/lib/python3.6/site-packages/rest_framework/views.py", line 465, in handle_exception
    self.raise_uncaught_exception(exc)
  File "/home/moluo/.virtualenvs/renran/lib/python3.6/site-packages/rest_framework/views.py", line 476, in raise_uncaught_exception
    raise exc
  File "/home/moluo/.virtualenvs/renran/lib/python3.6/site-packages/rest_framework/views.py", line 502, in dispatch
    response = handler(request, *args, **kwargs)
  File "/home/moluo/.virtualenvs/renran/lib/python3.6/site-packages/rest_framework/generics.py", line 190, in post
    return self.create(request, *args, **kwargs)
  File "/home/moluo/.virtualenvs/renran/lib/python3.6/site-packages/rest_framework/mixins.py", line 19, in create
    self.perform_create(serializer)
  File "/home/moluo/.virtualenvs/renran/lib/python3.6/site-packages/rest_framework/mixins.py", line 24, in perform_create
    serializer.save()
  File "/home/moluo/.virtualenvs/renran/lib/python3.6/site-packages/rest_framework/serializers.py", line 212, in save
    self.instance = self.create(validated_data)
  File "/home/moluo/.virtualenvs/renran/lib/python3.6/site-packages/rest_framework/serializers.py", line 967, in create
    raise TypeError(msg)
TypeError: Got a `TypeError` when calling `User.objects.create()`. This may be because you have a writable field on the serializer class that is not a valid argument to `User.objects.create()`. You may need to make the field read-only, or override the UserCreateModelSerializer.create() method to handle this correctly.
Original exception was:
 Traceback (most recent call last):
  File "/home/moluo/.virtualenvs/renran/lib/python3.6/site-packages/rest_framework/serializers.py", line 948, in create
    instance = ModelClass._default_manager.create(**validated_data)
  File "/home/moluo/.virtualenvs/renran/lib/python3.6/site-packages/django/db/models/manager.py", line 82, in manager_method
    return getattr(self.get_queryset(), name)(*args, **kwargs)
  File "/home/moluo/.virtualenvs/renran/lib/python3.6/site-packages/django/db/models/query.py", line 420, in create
    obj = self.model(**kwargs)
  File "/home/moluo/.virtualenvs/renran/lib/python3.6/site-packages/django/db/models/base.py", line 501, in __init__
    raise TypeError("%s() got an unexpected keyword argument '%s'" % (cls.__name__, kwarg))
TypeError: User() got an unexpected keyword argument 'sms_code'

ERROR 2020-03-03 20:27:47,577 basehttp 154 "POST /users/ HTTP/1.1" 500 21508
WARNING 2020-03-03 20:30:35,018 log 228 Not Found: /users/mobile/1381234567/
WARNING 2020-03-03 20:30:35,023 basehttp 154 "GET /users/mobile/1381234567/ HTTP/1.1" 404 2845
WARNING 2020-03-03 20:31:02,398 log 228 Not Found: /users/mobile/138123456/
WARNING 2020-03-03 20:31:02,399 basehttp 154 "GET /users/mobile/138123456/ HTTP/1.1" 404 2842
INFO 2020-03-03 20:34:12,472 autoreload 578 Watching for file changes with StatReloader
WARNING 2020-03-03 20:34:55,084 log 228 Not Found: /users/mobile/138123456/
WARNING 2020-03-03 20:34:55,182 basehttp 154 "GET /users/mobile/138123456/ HTTP/1.1" 404 2842
INFO 2020-03-03 20:35:36,160 basehttp 154 "GET /users/mobile/13838383838/ HTTP/1.1" 200 31
INFO 2020-03-03 20:35:43,601 basehttp 154 "OPTIONS /users/ HTTP/1.1" 200 0
WARNING 2020-03-03 20:35:43,623 log 228 Bad Request: /users/
WARNING 2020-03-03 20:35:43,623 basehttp 154 "POST /users/ HTTP/1.1" 400 61
WARNING 2020-03-03 20:35:49,483 log 228 Bad Request: /users/
WARNING 2020-03-03 20:35:49,484 basehttp 154 "POST /users/ HTTP/1.1" 400 61
ERROR 2020-03-03 20:39:21,169 log 228 Internal Server Error: /users/
Traceback (most recent call last):
  File "/home/moluo/.virtualenvs/renran/lib/python3.6/site-packages/rest_framework/serializers.py", line 948, in create
    instance = ModelClass._default_manager.create(**validated_data)
  File "/home/moluo/.virtualenvs/renran/lib/python3.6/site-packages/django/db/models/manager.py", line 82, in manager_method
    return getattr(self.get_queryset(), name)(*args, **kwargs)
  File "/home/moluo/.virtualenvs/renran/lib/python3.6/site-packages/django/db/models/query.py", line 420, in create
    obj = self.model(**kwargs)
  File "/home/moluo/.virtualenvs/renran/lib/python3.6/site-packages/django/db/models/base.py", line 501, in __init__
    raise TypeError("%s() got an unexpected keyword argument '%s'" % (cls.__name__, kwarg))
TypeError: User() got an unexpected keyword argument 'sms_code'

During handling of the above exception, another exception occurred:

Traceback (most recent call last):
  File "/home/moluo/.virtualenvs/renran/lib/python3.6/site-packages/django/core/handlers/exception.py", line 34, in inner
    response = get_response(request)
  File "/home/moluo/.virtualenvs/renran/lib/python3.6/site-packages/django/core/handlers/base.py", line 115, in _get_response
    response = self.process_exception_by_middleware(e, request)
  File "/home/moluo/.virtualenvs/renran/lib/python3.6/site-packages/django/core/handlers/base.py", line 113, in _get_response
    response = wrapped_callback(request, *callback_args, **callback_kwargs)
  File "/home/moluo/.virtualenvs/renran/lib/python3.6/site-packages/django/views/decorators/csrf.py", line 54, in wrapped_view
    return view_func(*args, **kwargs)
  File "/home/moluo/.virtualenvs/renran/lib/python3.6/site-packages/django/views/generic/base.py", line 71, in view
    return self.dispatch(request, *args, **kwargs)
  File "/home/moluo/.virtualenvs/renran/lib/python3.6/site-packages/rest_framework/views.py", line 505, in dispatch
    response = self.handle_exception(exc)
  File "/home/moluo/.virtualenvs/renran/lib/python3.6/site-packages/rest_framework/views.py", line 465, in handle_exception
    self.raise_uncaught_exception(exc)
  File "/home/moluo/.virtualenvs/renran/lib/python3.6/site-packages/rest_framework/views.py", line 476, in raise_uncaught_exception
    raise exc
  File "/home/moluo/.virtualenvs/renran/lib/python3.6/site-packages/rest_framework/views.py", line 502, in dispatch
    response = handler(request, *args, **kwargs)
  File "/home/moluo/.virtualenvs/renran/lib/python3.6/site-packages/rest_framework/generics.py", line 190, in post
    return self.create(request, *args, **kwargs)
  File "/home/moluo/.virtualenvs/renran/lib/python3.6/site-packages/rest_framework/mixins.py", line 19, in create
    self.perform_create(serializer)
  File "/home/moluo/.virtualenvs/renran/lib/python3.6/site-packages/rest_framework/mixins.py", line 24, in perform_create
    serializer.save()
  File "/home/moluo/.virtualenvs/renran/lib/python3.6/site-packages/rest_framework/serializers.py", line 212, in save
    self.instance = self.create(validated_data)
  File "/home/moluo/.virtualenvs/renran/lib/python3.6/site-packages/rest_framework/serializers.py", line 967, in create
    raise TypeError(msg)
TypeError: Got a `TypeError` when calling `User.objects.create()`. This may be because you have a writable field on the serializer class that is not a valid argument to `User.objects.create()`. You may need to make the field read-only, or override the UserCreateModelSerializer.create() method to handle this correctly.
Original exception was:
 Traceback (most recent call last):
  File "/home/moluo/.virtualenvs/renran/lib/python3.6/site-packages/rest_framework/serializers.py", line 948, in create
    instance = ModelClass._default_manager.create(**validated_data)
  File "/home/moluo/.virtualenvs/renran/lib/python3.6/site-packages/django/db/models/manager.py", line 82, in manager_method
    return getattr(self.get_queryset(), name)(*args, **kwargs)
  File "/home/moluo/.virtualenvs/renran/lib/python3.6/site-packages/django/db/models/query.py", line 420, in create
    obj = self.model(**kwargs)
  File "/home/moluo/.virtualenvs/renran/lib/python3.6/site-packages/django/db/models/base.py", line 501, in __init__
    raise TypeError("%s() got an unexpected keyword argument '%s'" % (cls.__name__, kwarg))
TypeError: User() got an unexpected keyword argument 'sms_code'

ERROR 2020-03-03 20:39:21,175 basehttp 154 "POST /users/ HTTP/1.1" 500 21508
INFO 2020-03-03 20:41:39,871 autoreload 578 Watching for file changes with StatReloader
INFO 2020-03-03 20:42:56,458 basehttp 154 "GET /users/mobile/13912345678/ HTTP/1.1" 200 31
INFO 2020-03-03 20:44:02,780 basehttp 154 "OPTIONS /users/ HTTP/1.1" 200 0
WARNING 2020-03-03 20:44:03,181 log 228 Bad Request: /users/
WARNING 2020-03-03 20:44:03,184 basehttp 154 "POST /users/ HTTP/1.1" 400 61
WARNING 2020-03-03 20:48:31,850 log 228 Not Found: /
WARNING 2020-03-03 20:48:31,860 basehttp 154 "GET / HTTP/1.1" 404 2035
WARNING 2020-03-03 20:48:32,096 log 228 Not Found: /favicon.ico
WARNING 2020-03-03 20:48:32,108 basehttp 154 "GET /favicon.ico HTTP/1.1" 404 2086
ERROR 2020-03-03 20:48:45,094 log 228 Internal Server Error: /users/captcha/
Traceback (most recent call last):
  File "/home/moluo/.virtualenvs/renran/lib/python3.6/site-packages/django/core/handlers/exception.py", line 34, in inner
    response = get_response(request)
  File "/home/moluo/.virtualenvs/renran/lib/python3.6/site-packages/django/core/handlers/base.py", line 145, in _get_response
    response = self.process_exception_by_middleware(e, request)
  File "/home/moluo/.virtualenvs/renran/lib/python3.6/site-packages/django/core/handlers/base.py", line 143, in _get_response
    response = response.render()
  File "/home/moluo/.virtualenvs/renran/lib/python3.6/site-packages/django/template/response.py", line 106, in render
    self.content = self.rendered_content
  File "/home/moluo/.virtualenvs/renran/lib/python3.6/site-packages/rest_framework/response.py", line 70, in rendered_content
    ret = renderer.render(self.data, accepted_media_type, context)
  File "/home/moluo/.virtualenvs/renran/lib/python3.6/site-packages/rest_framework/renderers.py", line 723, in render
    template = loader.get_template(self.template)
  File "/home/moluo/.virtualenvs/renran/lib/python3.6/site-packages/django/template/loader.py", line 19, in get_template
    raise TemplateDoesNotExist(template_name, chain=chain)
django.template.exceptions.TemplateDoesNotExist: rest_framework/api.html
ERROR 2020-03-03 20:48:45,096 basehttp 154 "GET /users/captcha/ HTTP/1.1" 500 89428
ERROR 2020-03-03 20:48:49,449 log 228 Internal Server Error: /users/
Traceback (most recent call last):
  File "/home/moluo/.virtualenvs/renran/lib/python3.6/site-packages/django/core/handlers/exception.py", line 34, in inner
    response = get_response(request)
  File "/home/moluo/.virtualenvs/renran/lib/python3.6/site-packages/django/core/handlers/base.py", line 145, in _get_response
    response = self.process_exception_by_middleware(e, request)
  File "/home/moluo/.virtualenvs/renran/lib/python3.6/site-packages/django/core/handlers/base.py", line 143, in _get_response
    response = response.render()
  File "/home/moluo/.virtualenvs/renran/lib/python3.6/site-packages/django/template/response.py", line 106, in render
    self.content = self.rendered_content
  File "/home/moluo/.virtualenvs/renran/lib/python3.6/site-packages/rest_framework/response.py", line 70, in rendered_content
    ret = renderer.render(self.data, accepted_media_type, context)
  File "/home/moluo/.virtualenvs/renran/lib/python3.6/site-packages/rest_framework/renderers.py", line 723, in render
    template = loader.get_template(self.template)
  File "/home/moluo/.virtualenvs/renran/lib/python3.6/site-packages/django/template/loader.py", line 19, in get_template
    raise TemplateDoesNotExist(template_name, chain=chain)
django.template.exceptions.TemplateDoesNotExist: rest_framework/api.html
ERROR 2020-03-03 20:48:49,450 basehttp 154 "GET /users/ HTTP/1.1" 500 89308
INFO 2020-03-03 20:50:11,288 basehttp 154 "GET /users/mobile/13912345678/ HTTP/1.1" 200 31
INFO 2020-03-03 20:50:13,956 basehttp 154 "OPTIONS /users/ HTTP/1.1" 200 0
WARNING 2020-03-03 20:50:13,978 log 228 Bad Request: /users/
WARNING 2020-03-03 20:50:13,984 basehttp 154 "POST /users/ HTTP/1.1" 400 61
WARNING 2020-03-03 20:50:18,667 log 228 Bad Request: /users/
WARNING 2020-03-03 20:50:18,668 basehttp 154 "POST /users/ HTTP/1.1" 400 61
INFO 2020-03-03 20:54:45,505 autoreload 203 /home/moluo/Desktop/renran/renranapi/renranapi/apps/users/serializers.py changed, reloading.
INFO 2020-03-03 20:54:48,514 autoreload 578 Watching for file changes with StatReloader
WARNING 2020-03-03 20:55:00,340 log 228 Bad Request: /users/
WARNING 2020-03-03 20:55:00,342 basehttp 154 "POST /users/ HTTP/1.1" 400 104
ERROR 2020-03-03 20:55:51,425 log 228 Internal Server Error: /users/
Traceback (most recent call last):
  File "/home/moluo/.virtualenvs/renran/lib/python3.6/site-packages/rest_framework/serializers.py", line 948, in create
    instance = ModelClass._default_manager.create(**validated_data)
  File "/home/moluo/.virtualenvs/renran/lib/python3.6/site-packages/django/db/models/manager.py", line 82, in manager_method
    return getattr(self.get_queryset(), name)(*args, **kwargs)
  File "/home/moluo/.virtualenvs/renran/lib/python3.6/site-packages/django/db/models/query.py", line 420, in create
    obj = self.model(**kwargs)
  File "/home/moluo/.virtualenvs/renran/lib/python3.6/site-packages/django/db/models/base.py", line 501, in __init__
    raise TypeError("%s() got an unexpected keyword argument '%s'" % (cls.__name__, kwarg))
TypeError: User() got an unexpected keyword argument 'sms_code'

During handling of the above exception, another exception occurred:

Traceback (most recent call last):
  File "/home/moluo/.virtualenvs/renran/lib/python3.6/site-packages/django/core/handlers/exception.py", line 34, in inner
    response = get_response(request)
  File "/home/moluo/.virtualenvs/renran/lib/python3.6/site-packages/django/core/handlers/base.py", line 115, in _get_response
    response = self.process_exception_by_middleware(e, request)
  File "/home/moluo/.virtualenvs/renran/lib/python3.6/site-packages/django/core/handlers/base.py", line 113, in _get_response
    response = wrapped_callback(request, *callback_args, **callback_kwargs)
  File "/home/moluo/.virtualenvs/renran/lib/python3.6/site-packages/django/views/decorators/csrf.py", line 54, in wrapped_view
    return view_func(*args, **kwargs)
  File "/home/moluo/.virtualenvs/renran/lib/python3.6/site-packages/django/views/generic/base.py", line 71, in view
    return self.dispatch(request, *args, **kwargs)
  File "/home/moluo/.virtualenvs/renran/lib/python3.6/site-packages/rest_framework/views.py", line 505, in dispatch
    response = self.handle_exception(exc)
  File "/home/moluo/.virtualenvs/renran/lib/python3.6/site-packages/rest_framework/views.py", line 465, in handle_exception
    self.raise_uncaught_exception(exc)
  File "/home/moluo/.virtualenvs/renran/lib/python3.6/site-packages/rest_framework/views.py", line 476, in raise_uncaught_exception
    raise exc
  File "/home/moluo/.virtualenvs/renran/lib/python3.6/site-packages/rest_framework/views.py", line 502, in dispatch
    response = handler(request, *args, **kwargs)
  File "/home/moluo/.virtualenvs/renran/lib/python3.6/site-packages/rest_framework/generics.py", line 190, in post
    return self.create(request, *args, **kwargs)
  File "/home/moluo/.virtualenvs/renran/lib/python3.6/site-packages/rest_framework/mixins.py", line 19, in create
    self.perform_create(serializer)
  File "/home/moluo/.virtualenvs/renran/lib/python3.6/site-packages/rest_framework/mixins.py", line 24, in perform_create
    serializer.save()
  File "/home/moluo/.virtualenvs/renran/lib/python3.6/site-packages/rest_framework/serializers.py", line 212, in save
    self.instance = self.create(validated_data)
  File "/home/moluo/.virtualenvs/renran/lib/python3.6/site-packages/rest_framework/serializers.py", line 967, in create
    raise TypeError(msg)
TypeError: Got a `TypeError` when calling `User.objects.create()`. This may be because you have a writable field on the serializer class that is not a valid argument to `User.objects.create()`. You may need to make the field read-only, or override the UserCreateModelSerializer.create() method to handle this correctly.
Original exception was:
 Traceback (most recent call last):
  File "/home/moluo/.virtualenvs/renran/lib/python3.6/site-packages/rest_framework/serializers.py", line 948, in create
    instance = ModelClass._default_manager.create(**validated_data)
  File "/home/moluo/.virtualenvs/renran/lib/python3.6/site-packages/django/db/models/manager.py", line 82, in manager_method
    return getattr(self.get_queryset(), name)(*args, **kwargs)
  File "/home/moluo/.virtualenvs/renran/lib/python3.6/site-packages/django/db/models/query.py", line 420, in create
    obj = self.model(**kwargs)
  File "/home/moluo/.virtualenvs/renran/lib/python3.6/site-packages/django/db/models/base.py", line 501, in __init__
    raise TypeError("%s() got an unexpected keyword argument '%s'" % (cls.__name__, kwarg))
TypeError: User() got an unexpected keyword argument 'sms_code'

ERROR 2020-03-03 20:55:51,435 basehttp 154 "POST /users/ HTTP/1.1" 500 21334
WARNING 2020-03-03 20:56:43,618 log 228 Bad Request: /users/
WARNING 2020-03-03 20:56:43,649 basehttp 154 "POST /users/ HTTP/1.1" 400 108
WARNING 2020-03-03 20:56:54,122 log 228 Bad Request: /users/
WARNING 2020-03-03 20:56:54,125 basehttp 154 "POST /users/ HTTP/1.1" 400 108
INFO 2020-03-03 21:00:46,009 basehttp 154 "GET /users/mobile/19929238507/ HTTP/1.1" 200 31
INFO 2020-03-03 21:00:55,055 basehttp 154 "OPTIONS /users/ HTTP/1.1" 200 0
ERROR 2020-03-03 21:00:55,747 log 228 Internal Server Error: /users/
Traceback (most recent call last):
  File "/home/moluo/.virtualenvs/renran/lib/python3.6/site-packages/rest_framework/serializers.py", line 948, in create
    instance = ModelClass._default_manager.create(**validated_data)
  File "/home/moluo/.virtualenvs/renran/lib/python3.6/site-packages/django/db/models/manager.py", line 82, in manager_method
    return getattr(self.get_queryset(), name)(*args, **kwargs)
  File "/home/moluo/.virtualenvs/renran/lib/python3.6/site-packages/django/db/models/query.py", line 420, in create
    obj = self.model(**kwargs)
  File "/home/moluo/.virtualenvs/renran/lib/python3.6/site-packages/django/db/models/base.py", line 501, in __init__
    raise TypeError("%s() got an unexpected keyword argument '%s'" % (cls.__name__, kwarg))
TypeError: User() got an unexpected keyword argument 'sms_code'

During handling of the above exception, another exception occurred:

Traceback (most recent call last):
  File "/home/moluo/.virtualenvs/renran/lib/python3.6/site-packages/django/core/handlers/exception.py", line 34, in inner
    response = get_response(request)
  File "/home/moluo/.virtualenvs/renran/lib/python3.6/site-packages/django/core/handlers/base.py", line 115, in _get_response
    response = self.process_exception_by_middleware(e, request)
  File "/home/moluo/.virtualenvs/renran/lib/python3.6/site-packages/django/core/handlers/base.py", line 113, in _get_response
    response = wrapped_callback(request, *callback_args, **callback_kwargs)
  File "/home/moluo/.virtualenvs/renran/lib/python3.6/site-packages/django/views/decorators/csrf.py", line 54, in wrapped_view
    return view_func(*args, **kwargs)
  File "/home/moluo/.virtualenvs/renran/lib/python3.6/site-packages/django/views/generic/base.py", line 71, in view
    return self.dispatch(request, *args, **kwargs)
  File "/home/moluo/.virtualenvs/renran/lib/python3.6/site-packages/rest_framework/views.py", line 505, in dispatch
    response = self.handle_exception(exc)
  File "/home/moluo/.virtualenvs/renran/lib/python3.6/site-packages/rest_framework/views.py", line 465, in handle_exception
    self.raise_uncaught_exception(exc)
  File "/home/moluo/.virtualenvs/renran/lib/python3.6/site-packages/rest_framework/views.py", line 476, in raise_uncaught_exception
    raise exc
  File "/home/moluo/.virtualenvs/renran/lib/python3.6/site-packages/rest_framework/views.py", line 502, in dispatch
    response = handler(request, *args, **kwargs)
  File "/home/moluo/.virtualenvs/renran/lib/python3.6/site-packages/rest_framework/generics.py", line 190, in post
    return self.create(request, *args, **kwargs)
  File "/home/moluo/.virtualenvs/renran/lib/python3.6/site-packages/rest_framework/mixins.py", line 19, in create
    self.perform_create(serializer)
  File "/home/moluo/.virtualenvs/renran/lib/python3.6/site-packages/rest_framework/mixins.py", line 24, in perform_create
    serializer.save()
  File "/home/moluo/.virtualenvs/renran/lib/python3.6/site-packages/rest_framework/serializers.py", line 212, in save
    self.instance = self.create(validated_data)
  File "/home/moluo/.virtualenvs/renran/lib/python3.6/site-packages/rest_framework/serializers.py", line 967, in create
    raise TypeError(msg)
TypeError: Got a `TypeError` when calling `User.objects.create()`. This may be because you have a writable field on the serializer class that is not a valid argument to `User.objects.create()`. You may need to make the field read-only, or override the UserCreateModelSerializer.create() method to handle this correctly.
Original exception was:
 Traceback (most recent call last):
  File "/home/moluo/.virtualenvs/renran/lib/python3.6/site-packages/rest_framework/serializers.py", line 948, in create
    instance = ModelClass._default_manager.create(**validated_data)
  File "/home/moluo/.virtualenvs/renran/lib/python3.6/site-packages/django/db/models/manager.py", line 82, in manager_method
    return getattr(self.get_queryset(), name)(*args, **kwargs)
  File "/home/moluo/.virtualenvs/renran/lib/python3.6/site-packages/django/db/models/query.py", line 420, in create
    obj = self.model(**kwargs)
  File "/home/moluo/.virtualenvs/renran/lib/python3.6/site-packages/django/db/models/base.py", line 501, in __init__
    raise TypeError("%s() got an unexpected keyword argument '%s'" % (cls.__name__, kwarg))
TypeError: User() got an unexpected keyword argument 'sms_code'

ERROR 2020-03-03 21:00:55,760 basehttp 154 "POST /users/ HTTP/1.1" 500 21508
INFO 2020-03-03 21:04:21,740 autoreload 578 Watching for file changes with StatReloader
INFO 2020-03-03 21:04:53,700 basehttp 154 "GET /users/mobile/19923289898/ HTTP/1.1" 200 31
ERROR 2020-03-03 21:04:57,199 log 228 Internal Server Error: /users/
Traceback (most recent call last):
  File "/home/moluo/.virtualenvs/renran/lib/python3.6/site-packages/django/core/handlers/exception.py", line 34, in inner
    response = get_response(request)
  File "/home/moluo/.virtualenvs/renran/lib/python3.6/site-packages/django/core/handlers/base.py", line 115, in _get_response
    response = self.process_exception_by_middleware(e, request)
  File "/home/moluo/.virtualenvs/renran/lib/python3.6/site-packages/django/core/handlers/base.py", line 113, in _get_response
    response = wrapped_callback(request, *callback_args, **callback_kwargs)
  File "/home/moluo/.virtualenvs/renran/lib/python3.6/site-packages/django/views/decorators/csrf.py", line 54, in wrapped_view
    return view_func(*args, **kwargs)
  File "/home/moluo/.virtualenvs/renran/lib/python3.6/site-packages/django/views/generic/base.py", line 71, in view
    return self.dispatch(request, *args, **kwargs)
  File "/home/moluo/.virtualenvs/renran/lib/python3.6/site-packages/rest_framework/views.py", line 505, in dispatch
    response = self.handle_exception(exc)
  File "/home/moluo/.virtualenvs/renran/lib/python3.6/site-packages/rest_framework/views.py", line 465, in handle_exception
    self.raise_uncaught_exception(exc)
  File "/home/moluo/.virtualenvs/renran/lib/python3.6/site-packages/rest_framework/views.py", line 476, in raise_uncaught_exception
    raise exc
  File "/home/moluo/.virtualenvs/renran/lib/python3.6/site-packages/rest_framework/views.py", line 502, in dispatch
    response = handler(request, *args, **kwargs)
  File "/home/moluo/.virtualenvs/renran/lib/python3.6/site-packages/rest_framework/generics.py", line 190, in post
    return self.create(request, *args, **kwargs)
  File "/home/moluo/.virtualenvs/renran/lib/python3.6/site-packages/rest_framework/mixins.py", line 18, in create
    serializer.is_valid(raise_exception=True)
  File "/home/moluo/.virtualenvs/renran/lib/python3.6/site-packages/rest_framework/serializers.py", line 234, in is_valid
    self._validated_data = self.run_validation(self.initial_data)
  File "/home/moluo/.virtualenvs/renran/lib/python3.6/site-packages/rest_framework/serializers.py", line 433, in run_validation
    value = self.to_internal_value(data)
  File "/home/moluo/.virtualenvs/renran/lib/python3.6/site-packages/rest_framework/serializers.py", line 486, in to_internal_value
    for field in fields:
  File "/home/moluo/.virtualenvs/renran/lib/python3.6/site-packages/rest_framework/serializers.py", line 369, in _writable_fields
    for field in self.fields.values():
  File "/home/moluo/.virtualenvs/renran/lib/python3.6/site-packages/django/utils/functional.py", line 80, in __get__
    res = instance.__dict__[self.name] = self.func(instance)
  File "/home/moluo/.virtualenvs/renran/lib/python3.6/site-packages/rest_framework/serializers.py", line 363, in fields
    for key, value in self.get_fields().items():
  File "/home/moluo/.virtualenvs/renran/lib/python3.6/site-packages/rest_framework/serializers.py", line 1038, in get_fields
    field_names = self.get_field_names(declared_fields, info)
  File "/home/moluo/.virtualenvs/renran/lib/python3.6/site-packages/rest_framework/serializers.py", line 1139, in get_field_names
    serializer_class=self.__class__.__name__
AssertionError: The field 'sms_code' was declared on serializer UserCreateModelSerializer, but has not been included in the 'fields' option.
ERROR 2020-03-03 21:04:57,202 basehttp 154 "POST /users/ HTTP/1.1" 500 19521
INFO 2020-03-03 21:06:11,699 autoreload 578 Watching for file changes with StatReloader
INFO 2020-03-03 21:06:33,500 basehttp 154 "GET /users/mobile/19929238507/ HTTP/1.1" 200 31
INFO 2020-03-03 21:06:37,906 basehttp 154 "POST /users/ HTTP/1.1" 201 246
INFO 2020-03-03 21:10:51,683 autoreload 578 Watching for file changes with StatReloader
INFO 2020-03-03 21:11:20,733 basehttp 154 "GET /users/mobile/13812345678/ HTTP/1.1" 200 31
INFO 2020-03-03 21:11:24,058 basehttp 154 "OPTIONS /users/ HTTP/1.1" 200 0
WARNING 2020-03-03 21:11:24,100 log 228 Bad Request: /users/
WARNING 2020-03-03 21:11:24,101 basehttp 154 "POST /users/ HTTP/1.1" 400 61
INFO 2020-03-03 21:11:28,900 basehttp 154 "POST /users/ HTTP/1.1" 201 247
INFO 2020-03-03 21:15:58,949 basehttp 154 "GET /users/mobile/19945678912/ HTTP/1.1" 200 31
WARNING 2020-03-03 21:16:06,114 log 228 Bad Request: /users/
WARNING 2020-03-03 21:16:06,126 basehttp 154 "POST /users/ HTTP/1.1" 400 61
WARNING 2020-03-03 21:16:41,418 log 228 Bad Request: /users/
WARNING 2020-03-03 21:16:41,420 basehttp 154 "POST /users/ HTTP/1.1" 400 61
